Workbook

Sheet Data
B2: ■ 한국맥널티㈜ 커피사업부 수금현황보고
B3: =TODAY()-1 -> 46272
B4: =NOW() -> 46273.599 | E4: 전월 마감 현황 | J4: =SUM($J$6:$J$10000)=SUMIFS(거래명세서품목조회!AN:AN, 거래명세서품목조회!G:G, ">="&(EOMONTH($B$3, -1)+1), 거래명세서품목조회!G:G, "<="&EOMONTH($B$3, 0)) -> TRUE | R4: *해외 음수 발생월 세부내역 확인 필수*
B5: 거래처명 | C5: 부서 | D5: 담당자 | E5: 이월잔액 | F5: 차변 | G5: 대변 | H5: 전월 미수액 | I5: =MONTH(B3) -> 9 | J5: =MONTH(B3) -> 9 | K5: 당월 수금액 | L5: 현 기준 잔액 | M5: 30일 이상 장기 미매출잔액 | N5: =J5 -> 9 | O5: =N5-1 -> 8 | P5: =O5-1 -> 7 | Q5: =P5-1 -> 6 | R5: 국내/외화
B6: {=_xlfn.UNIQUE(_xlfn._xlws.FILTER(_xlfn.VSTACK(거래명세서품목조회!BX2:BX99987, '관리항목계정별잔액조회(전월)'!C2:C99994,'관리항목계정별잔액조회(전전월)'!C2:C99994, '입금다중입력(잔액기준)'!E2:E50), _xlfn.VSTACK(거래명세서품목조회!BX2:BX99987, '관리항목계정별잔액조회(전월)'!C2:C99994,'관리항목계정별잔액조회(전전월)'!C2:C99994, '입금다중입력(잔액기준)'!E2:E50)<>""))} -> 디엔메디 | C6: =IFERROR(VLOOKUP(B6,거래처별담당자!C:F,4,0), "#미등록") -> CSO팀 | D6: =IF(ISNUMBER(SEARCH("애터미_수출",B6)),"애터미_수출",IF(ISNUMBER(SEARCH("애터미",B6)),"애터미",IF(ISNUMBER(SEARCH("매나테크",B6)),"매나테크",IF(ISNUMBER(SEARCH("Mannatech, Incorporated",B6)),"매나테크",IFERROR(VLOOKUP(B6,거래처별담당자!C:F,3,0),"#미등록"))))) -> 김화니 | E6: =SUMIF('관리항목계정별잔액조회(전월)'!$C:$C,B6,'관리항목계정별잔액조회(전월)'!$D:$D) -> 17894198 | F6: =SUMIF('관리항목계정별잔액조회(전월)'!$C:$C,B6,'관리항목계정별잔액조회(전월)'!$E:$E) -> 10692000 | G6: =SUMIF('관리항목계정별잔액조회(전월)'!$C:$C,B6,'관리항목계정별잔액조회(전월)'!$F:$F) -> 17894200 | H6: =SUMIF('관리항목계정별잔액조회(전월)'!$C:$C,B6,'관리항목계정별잔액조회(전월)'!$G:$G) -> 10691998 | I6: =SUMIFS(거래명세서품목조회!BK:BK, 거래명세서품목조회!BX:BX, B6, 거래명세서품목조회!G:G, "<"&(EOMONTH($B$3, -1)+1))+SUMIFS(부서별전표작성조회!$I:$I,부서별전표작성조회!$AG:$AG,B6,부서별전표작성조회!$F:$F,"국내외상매출금",부서별전표작성조회!$V:$V,"") -> 0 | J6: =SUMIFS(거래명세서품목조회!AN:AN, 거래명세서품목조회!BX:BX, B6, 거래명세서품목조회!G:G, ">="&(EOMONTH($B$3, -1)+1), 거래명세서품목조회!G:G, "<="&EOMONTH($B$3, 0)) -> 0 | K6: =SUMIFS('입금다중입력(잔액기준)'!$O:$O, '입금다중입력(잔액기준)'!$E:$E, B6, '입금다중입력(잔액기준)'!$M:$M, "국내외상매출금") -> 0 | L6: =IFERROR(H6+I6+J6-K6,0) -> 10691998 | M6: =SUMIFS(거래명세서품목조회!BK:BK, 거래명세서품목조회!BX:BX, B6, 거래명세서품목조회!G:G, "<="&(INT($B$4)-30)) -> 0 | N6: =MIN(L6, I6+J6) -> 0 | O6: =MIN(MAX(0, L6-N6), F6) -> 10691998 | P6: =MIN(MAX(0, L6-N6-O6), IFERROR(VLOOKUP(B6, '관리항목계정별잔액조회(전전월)'!$C:$E, 3, FALSE), 0)) -> 0 | Q6: =IF(H6=0, 0, MAX(0, L6-N6-O6-P6)) -> 0 | R6: =IF((COUNTIFS('관리항목계정별잔액조회(전월)'!$C:$C, B6, '관리항목계정별잔액조회(전월)'!$B:$B, "외화외상매출금") + COUNTIFS('관리항목계정별잔액조회(전전월)'!$C:$C, B6, '관리항목계정별잔액조회(전전월)'!$B:$B, "외화외상매출금")) > 0, "외화", "국내") -> 국내
B7: 동원약품남부 | C7: =IFERROR(VLOOKUP(B7,거래처별담당자!C:F,4,0), "#미등록") -> CSO팀 | D7: =IF(ISNUMBER(SEARCH("애터미_수출",B7)),"애터미_수출",IF(ISNUMBER(SEARCH("애터미",B7)),"애터미",IF(ISNUMBER(SEARCH("매나테크",B7)),"매나테크",IF(ISNUMBER(SEARCH("Mannatech, Incorporated",B7)),"매나테크",IFERROR(VLOOKUP(B7,거래처별담당자!C:F,3,0),"#미등록"))))) -> 김화니 | E7: =SUMIF('관리항목계정별잔액조회(전월)'!$C:$C,B7,'관리항목계정별잔액조회(전월)'!$D:$D) -> 9026760 | F7: =SUMIF('관리항목계정별잔액조회(전월)'!$C:$C,B7,'관리항목계정별잔액조회(전월)'!$E:$E) -> 3945150 | G7: =SUMIF('관리항목계정별잔액조회(전월)'!$C:$C,B7,'관리항목계정별잔액조회(전월)'!$F:$F) -> 7064280 | H7: =SUMIF('관리항목계정별잔액조회(전월)'!$C:$C,B7,'관리항목계정별잔액조회(전월)'!$G:$G) -> 5907630 | I7: =SUMIFS(거래명세서품목조회!BK:BK, 거래명세서품목조회!BX:BX, B7, 거래명세서품목조회!G:G, "<"&(EOMONTH($B$3, -1)+1))+SUMIFS(부서별전표작성조회!$I:$I,부서별전표작성조회!$AG:$AG,B7,부서별전표작성조회!$F:$F,"국내외상매출금",부서별전표작성조회!$V:$V,"") -> 0 | J7: =SUMIFS(거래명세서품목조회!AN:AN, 거래명세서품목조회!BX:BX, B7, 거래명세서품목조회!G:G, ">="&(EOMONTH($B$3, -1)+1), 거래명세서품목조회!G:G, "<="&EOMONTH($B$3, 0)) -> 0 | K7: =SUMIFS('입금다중입력(잔액기준)'!$O:$O, '입금다중입력(잔액기준)'!$E:$E, B7, '입금다중입력(잔액기준)'!$M:$M, "국내외상매출금") -> 0 | L7: =IFERROR(H7+I7+J7-K7,0) -> 5907630 | M7: =SUMIFS(거래명세서품목조회!BK:BK, 거래명세서품목조회!BX:BX, B7, 거래명세서품목조회!G:G, "<="&(INT($B$4)-30)) -> 0 | N7: =MIN(L7, I7+J7) -> 0 | O7: =MIN(MAX(0, L7-N7), F7) -> 3945150 | P7: =MIN(MAX(0, L7-N7-O7), IFERROR(VLOOKUP(B7, '관리항목계정별잔액조회(전전월)'!$C:$E, 3, FALSE), 0)) -> 1962480 | Q7: =IF(H7=0, 0, MAX(0, L7-N7-O7-P7)) -> 0 | R7: =IF((COUNTIFS('관리항목계정별잔액조회(전월)'!$C:$C, B7, '관리항목계정별잔액조회(전월)'!$B:$B, "외화외상매출금") + COUNTIFS('관리항목계정별잔액조회(전전월)'!$C:$C, B7, '관리항목계정별잔액조회(전전월)'!$B:$B, "외화외상매출금")) > 0, "외화", "국내") -> 국내
B8: 와이케이팜 | C8: =IFERROR(VLOOKUP(B8,거래처별담당자!C:F,4,0), "#미등록") -> CSO팀 | D8: =IF(ISNUMBER(SEARCH("애터미_수출",B8)),"애터미_수출",IF(ISNUMBER(SEARCH("애터미",B8)),"애터미",IF(ISNUMBER(SEARCH("매나테크",B8)),"매나테크",IF(ISNUMBER(SEARCH("Mannatech, Incorporated",B8)),"매나테크",IFERROR(VLOOKUP(B8,거래처별담당자!C:F,3,0),"#미등록"))))) -> 김화니 | E8: =SUMIF('관리항목계정별잔액조회(전월)'!$C:$C,B8,'관리항목계정별잔액조회(전월)'!$D:$D) -> 7779744 | F8: =SUMIF('관리항목계정별잔액조회(전월)'!$C:$C,B8,'관리항목계정별잔액조회(전월)'!$E:$E) -> 5720400 | G8: =SUMIF('관리항목계정별잔액조회(전월)'!$C:$C,B8,'관리항목계정별잔액조회(전월)'!$F:$F) -> 7779744 | H8: =SUMIF('관리항목계정별잔액조회(전월)'!$C:$C,B8,'관리항목계정별잔액조회(전월)'!$G:$G) -> 5720400 | I8: =SUMIFS(거래명세서품목조회!BK:BK, 거래명세서품목조회!BX:BX, B8, 거래명세서품목조회!G:G, "<"&(EOMONTH($B$3, -1)+1))+SUMIFS(부서별전표작성조회!$I:$I,부서별전표작성조회!$AG:$AG,B8,부서별전표작성조회!$F:$F,"국내외상매출금",부서별전표작성조회!$V:$V,"") -> 0 | J8: =SUMIFS(거래명세서품목조회!AN:AN, 거래명세서품목조회!BX:BX, B8, 거래명세서품목조회!G:G, ">="&(EOMONTH($B$3, -1)+1), 거래명세서품목조회!G:G, "<="&EOMONTH($B$3, 0)) -> 0 | K8: =SUMIFS('입금다중입력(잔액기준)'!$O:$O, '입금다중입력(잔액기준)'!$E:$E, B8, '입금다중입력(잔액기준)'!$M:$M, "국내외상매출금") -> 0 | L8: =IFERROR(H8+I8+J8-K8,0) -> 5720400 | M8: =SUMIFS(거래명세서품목조회!BK:BK, 거래명세서품목조회!BX:BX, B8, 거래명세서품목조회!G:G, "<="&(INT($B$4)-30)) -> 0 | N8: =MIN(L8, I8+J8) -> 0 | O8: =MIN(MAX(0, L8-N8), F8) -> 5720400 | P8: =MIN(MAX(0, L8-N8-O8), IFERROR(VLOOKUP(B8, '관리항목계정별잔액조회(전전월)'!$C:$E, 3, FALSE), 0)) -> 0 | Q8: =IF(H8=0, 0, MAX(0, L8-N8-O8-P8)) -> 0 | R8: =IF((COUNTIFS('관리항목계정별잔액조회(전월)'!$C:$C, B8, '관리항목계정별잔액조회(전월)'!$B:$B, "외화외상매출금") + COUNTIFS('관리항목계정별잔액조회(전전월)'!$C:$C, B8, '관리항목계정별잔액조회(전전월)'!$B:$B, "외화외상매출금")) > 0, "외화", "국내") -> 국내
B9: 우주약품 | C9: =IFERROR(VLOOKUP(B9,거래처별담당자!C:F,4,0), "#미등록") -> CSO팀 | D9: =IF(ISNUMBER(SEARCH("애터미_수출",B9)),"애터미_수출",IF(ISNUMBER(SEARCH("애터미",B9)),"애터미",IF(ISNUMBER(SEARCH("매나테크",B9)),"매나테크",IF(ISNUMBER(SEARCH("Mannatech, Incorporated",B9)),"매나테크",IFERROR(VLOOKUP(B9,거래처별담당자!C:F,3,0),"#미등록"))))) -> 김화니 | E9: =SUMIF('관리항목계정별잔액조회(전월)'!$C:$C,B9,'관리항목계정별잔액조회(전월)'!$D:$D) -> 3567780 | F9: =SUMIF('관리항목계정별잔액조회(전월)'!$C:$C,B9,'관리항목계정별잔액조회(전월)'!$E:$E) -> 3833190 | G9: =SUMIF('관리항목계정별잔액조회(전월)'!$C:$C,B9,'관리항목계정별잔액조회(전월)'!$F:$F) -> 3567780 | H9: =SUMIF('관리항목계정별잔액조회(전월)'!$C:$C,B9,'관리항목계정별잔액조회(전월)'!$G:$G) -> 3833190 | I9: =SUMIFS(거래명세서품목조회!BK:BK, 거래명세서품목조회!BX:BX, B9, 거래명세서품목조회!G:G, "<"&(EOMONTH($B$3, -1)+1))+SUMIFS(부서별전표작성조회!$I:$I,부서별전표작성조회!$AG:$AG,B9,부서별전표작성조회!$F:$F,"국내외상매출금",부서별전표작성조회!$V:$V,"") -> 0 | J9: =SUMIFS(거래명세서품목조회!AN:AN, 거래명세서품목조회!BX:BX, B9, 거래명세서품목조회!G:G, ">="&(EOMONTH($B$3, -1)+1), 거래명세서품목조회!G:G, "<="&EOMONTH($B$3, 0)) -> 0 | K9: =SUMIFS('입금다중입력(잔액기준)'!$O:$O, '입금다중입력(잔액기준)'!$E:$E, B9, '입금다중입력(잔액기준)'!$M:$M, "국내외상매출금") -> 0 | L9: =IFERROR(H9+I9+J9-K9,0) -> 3833190 | M9: =SUMIFS(거래명세서품목조회!BK:BK, 거래명세서품목조회!BX:BX, B9, 거래명세서품목조회!G:G, "<="&(INT($B$4)-30)) -> 0 | N9: =MIN(L9, I9+J9) -> 0 | O9: =MIN(MAX(0, L9-N9), F9) -> 3833190 | P9: =MIN(MAX(0, L9-N9-O9), IFERROR(VLOOKUP(B9, '관리항목계정별잔액조회(전전월)'!$C:$E, 3, FALSE), 0)) -> 0 | Q9: =IF(H9=0, 0, MAX(0, L9-N9-O9-P9)) -> 0 | R9: =IF((COUNTIFS('관리항목계정별잔액조회(전월)'!$C:$C, B9, '관리항목계정별잔액조회(전월)'!$B:$B, "외화외상매출금") + COUNTIFS('관리항목계정별잔액조회(전전월)'!$C:$C, B9, '관리항목계정별잔액조회(전전월)'!$B:$B, "외화외상매출금")) > 0, "외화", "국내") -> 국내
B10: 백제약품전주지점 | C10: =IFERROR(VLOOKUP(B10,거래처별담당자!C:F,4,0), "#미등록") -> CSO팀 | D10: =IF(ISNUMBER(SEARCH("애터미_수출",B10)),"애터미_수출",IF(ISNUMBER(SEARCH("애터미",B10)),"애터미",IF(ISNUMBER(SEARCH("매나테크",B10)),"매나테크",IF(ISNUMBER(SEARCH("Mannatech, Incorporated",B10)),"매나테크",IFERROR(VLOOKUP(B10,거래처별담당자!C:F,3,0),"#미등록"))))) -> 김화니 | E10: =SUMIF('관리항목계정별잔액조회(전월)'!$C:$C,B10,'관리항목계정별잔액조회(전월)'!$D:$D) -> 15674593 | F10: =SUMIF('관리항목계정별잔액조회(전월)'!$C:$C,B10,'관리항목계정별잔액조회(전월)'!$E:$E) -> 16733331 | G10: =SUMIF('관리항목계정별잔액조회(전월)'!$C:$C,B10,'관리항목계정별잔액조회(전월)'!$F:$F) -> 15680000 | H10: =SUMIF('관리항목계정별잔액조회(전월)'!$C:$C,B10,'관리항목계정별잔액조회(전월)'!$G:$G) -> 16727924 | I10: =SUMIFS(거래명세서품목조회!BK:BK, 거래명세서품목조회!BX:BX, B10, 거래명세서품목조회!G:G, "<"&(EOMONTH($B$3, -1)+1))+SUMIFS(부서별전표작성조회!$I:$I,부서별전표작성조회!$AG:$AG,B10,부서별전표작성조회!$F:$F,"국내외상매출금",부서별전표작성조회!$V:$V,"") -> 0 | J10: =SUMIFS(거래명세서품목조회!AN:AN, 거래명세서품목조회!BX:BX, B10, 거래명세서품목조회!G:G, ">="&(EOMONTH($B$3, -1)+1), 거래명세서품목조회!G:G, "<="&EOMONTH($B$3, 0)) -> 0 | K10: =SUMIFS('입금다중입력(잔액기준)'!$O:$O, '입금다중입력(잔액기준)'!$E:$E, B10, '입금다중입력(잔액기준)'!$M:$M, "국내외상매출금") -> 0 | L10: =IFERROR(H10+I10+J10-K10,0) -> 16727924 | M10: =SUMIFS(거래명세서품목조회!BK:BK, 거래명세서품목조회!BX:BX, B10, 거래명세서품목조회!G:G, "<="&(INT($B$4)-30)) -> 0 | N10: =MIN(L10, I10+J10) -> 0 | O10: =MIN(MAX(0, L10-N10), F10) -> 16727924 | P10: =MIN(MAX(0, L10-N10-O10), IFERROR(VLOOKUP(B10, '관리항목계정별잔액조회(전전월)'!$C:$E, 3, FALSE), 0)) -> 0 | Q10: =IF(H10=0, 0, MAX(0, L10-N10-O10-P10)) -> 0 | R10: =IF((COUNTIFS('관리항목계정별잔액조회(전월)'!$C:$C, B10, '관리항목계정별잔액조회(전월)'!$B:$B, "외화외상매출금") + COUNTIFS('관리항목계정별잔액조회(전전월)'!$C:$C, B10, '관리항목계정별잔액조회(전전월)'!$B:$B, "외화외상매출금")) > 0, "외화", "국내") -> 국내
B11: 예일선 | C11: =IFERROR(VLOOKUP(B11,거래처별담당자!C:F,4,0), "#미등록") -> CSO팀 | D11: =IF(ISNUMBER(SEARCH("애터미_수출",B11)),"애터미_수출",IF(ISNUMBER(SEARCH("애터미",B11)),"애터미",IF(ISNUMBER(SEARCH("매나테크",B11)),"매나테크",IF(ISNUMBER(SEARCH("Mannatech, Incorporated",B11)),"매나테크",IFERROR(VLOOKUP(B11,거래처별담당자!C:F,3,0),"#미등록"))))) -> 김화니 | E11: =SUMIF('관리항목계정별잔액조회(전월)'!$C:$C,B11,'관리항목계정별잔액조회(전월)'!$D:$D) -> 47326141 | F11: =SUMIF('관리항목계정별잔액조회(전월)'!$C:$C,B11,'관리항목계정별잔액조회(전월)'!$E:$E) -> 42297912 | G11: =SUMIF('관리항목계정별잔액조회(전월)'!$C:$C,B11,'관리항목계정별잔액조회(전월)'!$F:$F) -> 47326144 | H11: =SUMIF('관리항목계정별잔액조회(전월)'!$C:$C,B11,'관리항목계정별잔액조회(전월)'!$G:$G) -> 42297909 | I11: =SUMIFS(거래명세서품목조회!BK:BK, 거래명세서품목조회!BX:BX, B11, 거래명세서품목조회!G:G, "<"&(EOMONTH($B$3, -1)+1))+SUMIFS(부서별전표작성조회!$I:$I,부서별전표작성조회!$AG:$AG,B11,부서별전표작성조회!$F:$F,"국내외상매출금",부서별전표작성조회!$V:$V,"") -> 0 | J11: =SUMIFS(거래명세서품목조회!AN:AN, 거래명세서품목조회!BX:BX, B11, 거래명세서품목조회!G:G, ">="&(EOMONTH($B$3, -1)+1), 거래명세서품목조회!G:G, "<="&EOMONTH($B$3, 0)) -> 0 | K11: =SUMIFS('입금다중입력(잔액기준)'!$O:$O, '입금다중입력(잔액기준)'!$E:$E, B11, '입금다중입력(잔액기준)'!$M:$M, "국내외상매출금") -> 0 | L11: =IFERROR(H11+I11+J11-K11,0) -> 42297909 | M11: =SUMIFS(거래명세서품목조회!BK:BK, 거래명세서품목조회!BX:BX, B11, 거래명세서품목조회!G:G, "<="&(INT($B$4)-30)) -> 0 | N11: =MIN(L11, I11+J11) -> 0 | O11: =MIN(MAX(0, L11-N11), F11) -> 42297909 | P11: =MIN(MAX(0, L11-N11-O11), IFERROR(VLOOKUP(B11, '관리항목계정별잔액조회(전전월)'!$C:$E, 3, FALSE), 0)) -> 0 | Q11: =IF(H11=0, 0, MAX(0, L11-N11-O11-P11)) -> 0 | R11: =IF((COUNTIFS('관리항목계정별잔액조회(전월)'!$C:$C, B11, '관리항목계정별잔액조회(전월)'!$B:$B, "외화외상매출금") + COUNTIFS('관리항목계정별잔액조회(전전월)'!$C:$C, B11, '관리항목계정별잔액조회(전전월)'!$B:$B, "외화외상매출금")) > 0, "외화", "국내") -> 국내
B12: 훈민약품 | C12: =IFERROR(VLOOKUP(B12,거래처별담당자!C:F,4,0), "#미등록") -> CSO팀 | D12: =IF(ISNUMBER(SEARCH("애터미_수출",B12)),"애터미_수출",IF(ISNUMBER(SEARCH("애터미",B12)),"애터미",IF(ISNUMBER(SEARCH("매나테크",B12)),"매나테크",IF(ISNUMBER(SEARCH("Mannatech, Incorporated",B12)),"매나테크",IFERROR(VLOOKUP(B12,거래처별담당자!C:F,3,0),"#미등록"))))) -> 김화니 | E12: =SUMIF('관리항목계정별잔액조회(전월)'!$C:$C,B12,'관리항목계정별잔액조회(전월)'!$D:$D) -> 435600 | F12: =SUMIF('관리항목계정별잔액조회(전월)'!$C:$C,B12,'관리항목계정별잔액조회(전월)'!$E:$E) -> 732600 | G12: =SUMIF('관리항목계정별잔액조회(전월)'!$C:$C,B12,'관리항목계정별잔액조회(전월)'!$F:$F) -> 435600 | H12: =SUMIF('관리항목계정별잔액조회(전월)'!$C:$C,B12,'관리항목계정별잔액조회(전월)'!$G:$G) -> 732600 | I12: =SUMIFS(거래명세서품목조회!BK:BK, 거래명세서품목조회!BX:BX, B12, 거래명세서품목조회!G:G, "<"&(EOMONTH($B$3, -1)+1))+SUMIFS(부서별전표작성조회!$I:$I,부서별전표작성조회!$AG:$AG,B12,부서별전표작성조회!$F:$F,"국내외상매출금",부서별전표작성조회!$V:$V,"") -> 0 | J12: =SUMIFS(거래명세서품목조회!AN:AN, 거래명세서품목조회!BX:BX, B12, 거래명세서품목조회!G:G, ">="&(EOMONTH($B$3, -1)+1), 거래명세서품목조회!G:G, "<="&EOMONTH($B$3, 0)) -> 0 | K12: =SUMIFS('입금다중입력(잔액기준)'!$O:$O, '입금다중입력(잔액기준)'!$E:$E, B12, '입금다중입력(잔액기준)'!$M:$M, "국내외상매출금") -> 0 | L12: =IFERROR(H12+I12+J12-K12,0) -> 732600 | M12: =SUMIFS(거래명세서품목조회!BK:BK, 거래명세서품목조회!BX:BX, B12, 거래명세서품목조회!G:G, "<="&(INT($B$4)-30)) -> 0 | N12: =MIN(L12, I12+J12) -> 0 | O12: =MIN(MAX(0, L12-N12), F12) -> 732600 | P12: =MIN(MAX(0, L12-N12-O12), IFERROR(VLOOKUP(B12, '관리항목계정별잔액조회(전전월)'!$C:$E, 3, FALSE), 0)) -> 0 | Q12: =IF(H12=0, 0, MAX(0, L12-N12-O12-P12)) -> 0 | R12: =IF((COUNTIFS('관리항목계정별잔액조회(전월)'!$C:$C, B12, '관리항목계정별잔액조회(전월)'!$B:$B, "외화외상매출금") + COUNTIFS('관리항목계정별잔액조회(전전월)'!$C:$C, B12, '관리항목계정별잔액조회(전전월)'!$B:$B, "외화외상매출금")) > 0, "외화", "국내") -> 국내
B13: 에스바이오 | C13: =IFERROR(VLOOKUP(B13,거래처별담당자!C:F,4,0), "#미등록") -> CSO팀 | D13: =IF(ISNUMBER(SEARCH("애터미_수출",B13)),"애터미_수출",IF(ISNUMBER(SEARCH("애터미",B13)),"애터미",IF(ISNUMBER(SEARCH("매나테크",B13)),"매나테크",IF(ISNUMBER(SEARCH("Mannatech, Incorporated",B13)),"매나테크",IFERROR(VLOOKUP(B13,거래처별담당자!C:F,3,0),"#미등록"))))) -> 김화니 | E13: =SUMIF('관리항목계정별잔액조회(전월)'!$C:$C,B13,'관리항목계정별잔액조회(전월)'!$D:$D) -> 11092676 | F13: =SUMIF('관리항목계정별잔액조회(전월)'!$C:$C,B13,'관리항목계정별잔액조회(전월)'!$E:$E) -> 7434634 | G13: =SUMIF('관리항목계정별잔액조회(전월)'!$C:$C,B13,'관리항목계정별잔액조회(전월)'!$F:$F) -> 16280640 | H13: =SUMIF('관리항목계정별잔액조회(전월)'!$C:$C,B13,'관리항목계정별잔액조회(전월)'!$G:$G) -> 2246670 | I13: =SUMIFS(거래명세서품목조회!BK:BK, 거래명세서품목조회!BX:BX, B13, 거래명세서품목조회!G:G, "<"&(EOMONTH($B$3, -1)+1))+SUMIFS(부서별전표작성조회!$I:$I,부서별전표작성조회!$AG:$AG,B13,부서별전표작성조회!$F:$F,"국내외상매출금",부서별전표작성조회!$V:$V,"") -> 0 | J13: =SUMIFS(거래명세서품목조회!AN:AN, 거래명세서품목조회!BX:BX, B13, 거래명세서품목조회!G:G, ">="&(EOMONTH($B$3, -1)+1), 거래명세서품목조회!G:G, "<="&EOMONTH($B$3, 0)) -> 0 | K13: =SUMIFS('입금다중입력(잔액기준)'!$O:$O, '입금다중입력(잔액기준)'!$E:$E, B13, '입금다중입력(잔액기준)'!$M:$M, "국내외상매출금") -> 0 | L13: =IFERROR(H13+I13+J13-K13,0) -> 2246670 | M13: =SUMIFS(거래명세서품목조회!BK:BK, 거래명세서품목조회!BX:BX, B13, 거래명세서품목조회!G:G, "<="&(INT($B$4)-30)) -> 0 | N13: =MIN(L13, I13+J13) -> 0 | O13: =MIN(MAX(0, L13-N13), F13) -> 2246670 | P13: =MIN(MAX(0, L13-N13-O13), IFERROR(VLOOKUP(B13, '관리항목계정별잔액조회(전전월)'!$C:$E, 3, FALSE), 0)) -> 0 | Q13: =IF(H13=0, 0, MAX(0, L13-N13-O13-P13)) -> 0 | R13: =IF((COUNTIFS('관리항목계정별잔액조회(전월)'!$C:$C, B13, '관리항목계정별잔액조회(전월)'!$B:$B, "외화외상매출금") + COUNTIFS('관리항목계정별잔액조회(전전월)'!$C:$C, B13, '관리항목계정별잔액조회(전전월)'!$B:$B, "외화외상매출금")) > 0, "외화", "국내") -> 국내
B14: 백제약품광주 | C14: =IFERROR(VLOOKUP(B14,거래처별담당자!C:F,4,0), "#미등록") -> CSO팀 | D14: =IF(ISNUMBER(SEARCH("애터미_수출",B14)),"애터미_수출",IF(ISNUMBER(SEARCH("애터미",B14)),"애터미",IF(ISNUMBER(SEARCH("매나테크",B14)),"매나테크",IF(ISNUMBER(SEARCH("Mannatech, Incorporated",B14)),"매나테크",IFERROR(VLOOKUP(B14,거래처별담당자!C:F,3,0),"#미등록"))))) -> 김화니 | E14: =SUMIF('관리항목계정별잔액조회(전월)'!$C:$C,B14,'관리항목계정별잔액조회(전월)'!$D:$D) -> 17012960 | F14: =SUMIF('관리항목계정별잔액조회(전월)'!$C:$C,B14,'관리항목계정별잔액조회(전월)'!$E:$E) -> 12523410 | G14: =SUMIF('관리항목계정별잔액조회(전월)'!$C:$C,B14,'관리항목계정별잔액조회(전월)'!$F:$F) -> 17012970 | H14: =SUMIF('관리항목계정별잔액조회(전월)'!$C:$C,B14,'관리항목계정별잔액조회(전월)'!$G:$G) -> 12523400 | I14: =SUMIFS(거래명세서품목조회!BK:BK, 거래명세서품목조회!BX:BX, B14, 거래명세서품목조회!G:G, "<"&(EOMONTH($B$3, -1)+1))+SUMIFS(부서별전표작성조회!$I:$I,부서별전표작성조회!$AG:$AG,B14,부서별전표작성조회!$F:$F,"국내외상매출금",부서별전표작성조회!$V:$V,"") -> 0 | J14: =SUMIFS(거래명세서품목조회!AN:AN, 거래명세서품목조회!BX:BX, B14, 거래명세서품목조회!G:G, ">="&(EOMONTH($B$3, -1)+1), 거래명세서품목조회!G:G, "<="&EOMONTH($B$3, 0)) -> 0 | K14: =SUMIFS('입금다중입력(잔액기준)'!$O:$O, '입금다중입력(잔액기준)'!$E:$E, B14, '입금다중입력(잔액기준)'!$M:$M, "국내외상매출금") -> 0 | L14: =IFERROR(H14+I14+J14-K14,0) -> 12523400 | M14: =SUMIFS(거래명세서품목조회!BK:BK, 거래명세서품목조회!BX:BX, B14, 거래명세서품목조회!G:G, "<="&(INT($B$4)-30)) -> 0 | N14: =MIN(L14, I14+J14) -> 0 | O14: =MIN(MAX(0, L14-N14), F14) -> 12523400 | P14: =MIN(MAX(0, L14-N14-O14), IFERROR(VLOOKUP(B14, '관리항목계정별잔액조회(전전월)'!$C:$E, 3, FALSE), 0)) -> 0 | Q14: =IF(H14=0, 0, MAX(0, L14-N14-O14-P14)) -> 0 | R14: =IF((COUNTIFS('관리항목계정별잔액조회(전월)'!$C:$C, B14, '관리항목계정별잔액조회(전월)'!$B:$B, "외화외상매출금") + COUNTIFS('관리항목계정별잔액조회(전전월)'!$C:$C, B14, '관리항목계정별잔액조회(전전월)'!$B:$B, "외화외상매출금")) > 0, "외화", "국내") -> 국내
B15: 강원지오영 | C15: =IFERROR(VLOOKUP(B15,거래처별담당자!C:F,4,0), "#미등록") -> CSO팀 | D15: =IF(ISNUMBER(SEARCH("애터미_수출",B15)),"애터미_수출",IF(ISNUMBER(SEARCH("애터미",B15)),"애터미",IF(ISNUMBER(SEARCH("매나테크",B15)),"매나테크",IF(ISNUMBER(SEARCH("Mannatech, Incorporated",B15)),"매나테크",IFERROR(VLOOKUP(B15,거래처별담당자!C:F,3,0),"#미등록"))))) -> 김화니 | E15: =SUMIF('관리항목계정별잔액조회(전월)'!$C:$C,B15,'관리항목계정별잔액조회(전월)'!$D:$D) -> 16094654 | F15: =SUMIF('관리항목계정별잔액조회(전월)'!$C:$C,B15,'관리항목계정별잔액조회(전월)'!$E:$E) -> 9425934 | G15: =SUMIF('관리항목계정별잔액조회(전월)'!$C:$C,B15,'관리항목계정별잔액조회(전월)'!$F:$F) -> 14470184 | H15: =SUMIF('관리항목계정별잔액조회(전월)'!$C:$C,B15,'관리항목계정별잔액조회(전월)'!$G:$G) -> 11050404 | I15: =SUMIFS(거래명세서품목조회!BK:BK, 거래명세서품목조회!BX:BX, B15, 거래명세서품목조회!G:G, "<"&(EOMONTH($B$3, -1)+1))+SUMIFS(부서별전표작성조회!$I:$I,부서별전표작성조회!$AG:$AG,B15,부서별전표작성조회!$F:$F,"국내외상매출금",부서별전표작성조회!$V:$V,"") -> 0 | J15: =SUMIFS(거래명세서품목조회!AN:AN, 거래명세서품목조회!BX:BX, B15, 거래명세서품목조회!G:G, ">="&(EOMONTH($B$3, -1)+1), 거래명세서품목조회!G:G, "<="&EOMONTH($B$3, 0)) -> 0 | K15: =SUMIFS('입금다중입력(잔액기준)'!$O:$O, '입금다중입력(잔액기준)'!$E:$E, B15, '입금다중입력(잔액기준)'!$M:$M, "국내외상매출금") -> 0 | L15: =IFERROR(H15+I15+J15-K15,0) -> 11050404 | M15: =SUMIFS(거래명세서품목조회!BK:BK, 거래명세서품목조회!BX:BX, B15, 거래명세서품목조회!G:G, "<="&(INT($B$4)-30)) -> 0 | N15: =MIN(L15, I15+J15) -> 0 | O15: =MIN(MAX(0, L15-N15), F15) -> 9425934 | P15: =MIN(MAX(0, L15-N15-O15), IFERROR(VLOOKUP(B15, '관리항목계정별잔액조회(전전월)'!$C:$E, 3, FALSE), 0)) -> 1624470 | Q15: =IF(H15=0, 0, MAX(0, L15-N15-O15-P15)) -> 0 | R15: =IF((COUNTIFS('관리항목계정별잔액조회(전월)'!$C:$C, B15, '관리항목계정별잔액조회(전월)'!$B:$B, "외화외상매출금") + COUNTIFS('관리항목계정별잔액조회(전전월)'!$C:$C, B15, '관리항목계정별잔액조회(전전월)'!$B:$B, "외화외상매출금")) > 0, "외화", "국내") -> 국내
B16: 제이씨헬스케어 | C16: =IFERROR(VLOOKUP(B16,거래처별담당자!C:F,4,0), "#미등록") -> CSO팀 | D16: =IF(ISNUMBER(SEARCH("애터미_수출",B16)),"애터미_수출",IF(ISNUMBER(SEARCH("애터미",B16)),"애터미",IF(ISNUMBER(SEARCH("매나테크",B16)),"매나테크",IF(ISNUMBER(SEARCH("Mannatech, Incorporated",B16)),"매나테크",IFERROR(VLOOKUP(B16,거래처별담당자!C:F,3,0),"#미등록"))))) -> 김화니 | E16: =SUMIF('관리항목계정별잔액조회(전월)'!$C:$C,B16,'관리항목계정별잔액조회(전월)'!$D:$D) -> 4536000 | F16: =SUMIF('관리항목계정별잔액조회(전월)'!$C:$C,B16,'관리항목계정별잔액조회(전월)'!$E:$E) -> 6048000 | G16: =SUMIF('관리항목계정별잔액조회(전월)'!$C:$C,B16,'관리항목계정별잔액조회(전월)'!$F:$F) -> 4536000 | H16: =SUMIF('관리항목계정별잔액조회(전월)'!$C:$C,B16,'관리항목계정별잔액조회(전월)'!$G:$G) -> 6048000 | I16: =SUMIFS(거래명세서품목조회!BK:BK, 거래명세서품목조회!BX:BX, B16, 거래명세서품목조회!G:G, "<"&(EOMONTH($B$3, -1)+1))+SUMIFS(부서별전표작성조회!$I:$I,부서별전표작성조회!$AG:$AG,B16,부서별전표작성조회!$F:$F,"국내외상매출금",부서별전표작성조회!$V:$V,"") -> 0 | J16: =SUMIFS(거래명세서품목조회!AN:AN, 거래명세서품목조회!BX:BX, B16, 거래명세서품목조회!G:G, ">="&(EOMONTH($B$3, -1)+1), 거래명세서품목조회!G:G, "<="&EOMONTH($B$3, 0)) -> 0 | K16: =SUMIFS('입금다중입력(잔액기준)'!$O:$O, '입금다중입력(잔액기준)'!$E:$E, B16, '입금다중입력(잔액기준)'!$M:$M, "국내외상매출금") -> 0 | L16: =IFERROR(H16+I16+J16-K16,0) -> 6048000 | M16: =SUMIFS(거래명세서품목조회!BK:BK, 거래명세서품목조회!BX:BX, B16, 거래명세서품목조회!G:G, "<="&(INT($B$4)-30)) -> 0 | N16: =MIN(L16, I16+J16) -> 0 | O16: =MIN(MAX(0, L16-N16), F16) -> 6048000 | P16: =MIN(MAX(0, L16-N16-O16), IFERROR(VLOOKUP(B16, '관리항목계정별잔액조회(전전월)'!$C:$E, 3, FALSE), 0)) -> 0 | Q16: =IF(H16=0, 0, MAX(0, L16-N16-O16-P16)) -> 0 | R16: =IF((COUNTIFS('관리항목계정별잔액조회(전월)'!$C:$C, B16, '관리항목계정별잔액조회(전월)'!$B:$B, "외화외상매출금") + COUNTIFS('관리항목계정별잔액조회(전전월)'!$C:$C, B16, '관리항목계정별잔액조회(전전월)'!$B:$B, "외화외상매출금")) > 0, "외화", "국내") -> 국내
B17: 대경엘씨에스디 | C17: =IFERROR(VLOOKUP(B17,거래처별담당자!C:F,4,0), "#미등록") -> CSO팀 | D17: =IF(ISNUMBER(SEARCH("애터미_수출",B17)),"애터미_수출",IF(ISNUMBER(SEARCH("애터미",B17)),"애터미",IF(ISNUMBER(SEARCH("매나테크",B17)),"매나테크",IF(ISNUMBER(SEARCH("Mannatech, Incorporated",B17)),"매나테크",IFERROR(VLOOKUP(B17,거래처별담당자!C:F,3,0),"#미등록"))))) -> 김화니 | E17: =SUMIF('관리항목계정별잔액조회(전월)'!$C:$C,B17,'관리항목계정별잔액조회(전월)'!$D:$D) -> 16030794 | F17: =SUMIF('관리항목계정별잔액조회(전월)'!$C:$C,B17,'관리항목계정별잔액조회(전월)'!$E:$E) -> 4565925 | G17: =SUMIF('관리항목계정별잔액조회(전월)'!$C:$C,B17,'관리항목계정별잔액조회(전월)'!$F:$F) -> 16030800 | H17: =SUMIF('관리항목계정별잔액조회(전월)'!$C:$C,B17,'관리항목계정별잔액조회(전월)'!$G:$G) -> 4565919 | I17: =SUMIFS(거래명세서품목조회!BK:BK, 거래명세서품목조회!BX:BX, B17, 거래명세서품목조회!G:G, "<"&(EOMONTH($B$3, -1)+1))+SUMIFS(부서별전표작성조회!$I:$I,부서별전표작성조회!$AG:$AG,B17,부서별전표작성조회!$F:$F,"국내외상매출금",부서별전표작성조회!$V:$V,"") -> 0 | J17: =SUMIFS(거래명세서품목조회!AN:AN, 거래명세서품목조회!BX:BX, B17, 거래명세서품목조회!G:G, ">="&(EOMONTH($B$3, -1)+1), 거래명세서품목조회!G:G, "<="&EOMONTH($B$3, 0)) -> 0 | K17: =SUMIFS('입금다중입력(잔액기준)'!$O:$O, '입금다중입력(잔액기준)'!$E:$E, B17, '입금다중입력(잔액기준)'!$M:$M, "국내외상매출금") -> 0 | L17: =IFERROR(H17+I17+J17-K17,0) -> 4565919 | M17: =SUMIFS(거래명세서품목조회!BK:BK, 거래명세서품목조회!BX:BX, B17, 거래명세서품목조회!G:G, "<="&(INT($B$4)-30)) -> 0 | N17: =MIN(L17, I17+J17) -> 0 | O17: =MIN(MAX(0, L17-N17), F17) -> 4565919 | P17: =MIN(MAX(0, L17-N17-O17), IFERROR(VLOOKUP(B17, '관리항목계정별잔액조회(전전월)'!$C:$E, 3, FALSE), 0)) -> 0 | Q17: =IF(H17=0, 0, MAX(0, L17-N17-O17-P17)) -> 0 | R17: =IF((COUNTIFS('관리항목계정별잔액조회(전월)'!$C:$C, B17, '관리항목계정별잔액조회(전월)'!$B:$B, "외화외상매출금") + COUNTIFS('관리항목계정별잔액조회(전전월)'!$C:$C, B17, '관리항목계정별잔액조회(전전월)'!$B:$B, "외화외상매출금")) > 0, "외화", "국내") -> 국내
B18: 지오영 | C18: =IFERROR(VLOOKUP(B18,거래처별담당자!C:F,4,0), "#미등록") -> CSO팀 | D18: =IF(ISNUMBER(SEARCH("애터미_수출",B18)),"애터미_수출",IF(ISNUMBER(SEARCH("애터미",B18)),"애터미",IF(ISNUMBER(SEARCH("매나테크",B18)),"매나테크",IF(ISNUMBER(SEARCH("Mannatech, Incorporated",B18)),"매나테크",IFERROR(VLOOKUP(B18,거래처별담당자!C:F,3,0),"#미등록"))))) -> 김화니 | E18: =SUMIF('관리항목계정별잔액조회(전월)'!$C:$C,B18,'관리항목계정별잔액조회(전월)'!$D:$D) -> 480411806 | F18: =SUMIF('관리항목계정별잔액조회(전월)'!$C:$C,B18,'관리항목계정별잔액조회(전월)'!$E:$E) -> 189271307 | G18: =SUMIF('관리항목계정별잔액조회(전월)'!$C:$C,B18,'관리항목계정별잔액조회(전월)'!$F:$F) -> 230000000 | H18: =SUMIF('관리항목계정별잔액조회(전월)'!$C:$C,B18,'관리항목계정별잔액조회(전월)'!$G:$G) -> 439683113 | I18: =SUMIFS(거래명세서품목조회!BK:BK, 거래명세서품목조회!BX:BX, B18, 거래명세서품목조회!G:G, "<"&(EOMONTH($B$3, -1)+1))+SUMIFS(부서별전표작성조회!$I:$I,부서별전표작성조회!$AG:$AG,B18,부서별전표작성조회!$F:$F,"국내외상매출금",부서별전표작성조회!$V:$V,"") -> 0 | J18: =SUMIFS(거래명세서품목조회!AN:AN, 거래명세서품목조회!BX:BX, B18, 거래명세서품목조회!G:G, ">="&(EOMONTH($B$3, -1)+1), 거래명세서품목조회!G:G, "<="&EOMONTH($B$3, 0)) -> 0 | K18: =SUMIFS('입금다중입력(잔액기준)'!$O:$O, '입금다중입력(잔액기준)'!$E:$E, B18, '입금다중입력(잔액기준)'!$M:$M, "국내외상매출금") -> 0 | L18: =IFERROR(H18+I18+J18-K18,0) -> 439683113 | M18: =SUMIFS(거래명세서품목조회!BK:BK, 거래명세서품목조회!BX:BX, B18, 거래명세서품목조회!G:G, "<="&(INT($B$4)-30)) -> 0 | N18: =MIN(L18, I18+J18) -> 0 | O18: =MIN(MAX(0, L18-N18), F18) -> 189271307 | P18: =MIN(MAX(0, L18-N18-O18), IFERROR(VLOOKUP(B18, '관리항목계정별잔액조회(전전월)'!$C:$E, 3, FALSE), 0)) -> 227338482 | Q18: =IF(H18=0, 0, MAX(0, L18-N18-O18-P18)) -> 23073324 | R18: =IF((COUNTIFS('관리항목계정별잔액조회(전월)'!$C:$C, B18, '관리항목계정별잔액조회(전월)'!$B:$B, "외화외상매출금") + COUNTIFS('관리항목계정별잔액조회(전전월)'!$C:$C, B18, '관리항목계정별잔액조회(전전월)'!$B:$B, "외화외상매출금")) > 0, "외화", "국내") -> 국내
... B118: 메디팜스 | C118: =IFERROR(VLOOKUP(B118,거래처별담당자!C:F,4,0), "#미등록") -> CSO팀 | D118: =IF(ISNUMBER(SEARCH("애터미_수출",B118)),"애터미_수출",IF(ISNUMBER(SEARCH("애터미",B118)),"애터미",IF(ISNUMBER(SEARCH("매나테크",B118)),"매나테크",IF(ISNUMBER(SEARCH("Mannatech, Incorporated",B118)),"매나테크",IFERROR(VLOOKUP(B118,거래처별담당자!C:F,3,0),"#미등록"))))) -> 김화니 | E118: =SUMIF('관리항목계정별잔액조회(전월)'!$C:$C,B118,'관리항목계정별잔액조회(전월)'!$D:$D) -> 0 | F118: =SUMIF('관리항목계정별잔액조회(전월)'!$C:$C,B118,'관리항목계정별잔액조회(전월)'!$E:$E) -> 0 | G118: =SUMIF('관리항목계정별잔액조회(전월)'!$C:$C,B118,'관리항목계정별잔액조회(전월)'!$F:$F) -> 0 | H118: =SUMIF('관리항목계정별잔액조회(전월)'!$C:$C,B118,'관리항목계정별잔액조회(전월)'!$G:$G) -> 0 | I118: =SUMIFS(거래명세서품목조회!BK:BK, 거래명세서품목조회!BX:BX, B118, 거래명세서품목조회!G:G, "<"&(EOMONTH($B$3, -1)+1))+SUMIFS(부서별전표작성조회!$I:$I,부서별전표작성조회!$AG:$AG,B118,부서별전표작성조회!$F:$F,"국내외상매출금",부서별전표작성조회!$V:$V,"") -> 0 | J118: =SUMIFS(거래명세서품목조회!AN:AN, 거래명세서품목조회!BX:BX, B118, 거래명세서품목조회!G:G, ">="&(EOMONTH($B$3, -1)+1), 거래명세서품목조회!G:G, "<="&EOMONTH($B$3, 0)) -> 0 | K118: =SUMIFS('입금다중입력(잔액기준)'!$O:$O, '입금다중입력(잔액기준)'!$E:$E, B118, '입금다중입력(잔액기준)'!$M:$M, "국내외상매출금") -> 0 | L118: =IFERROR(H118+I118+J118-K118,0) -> 0 | M118: =SUMIFS(거래명세서품목조회!BK:BK, 거래명세서품목조회!BX:BX, B118, 거래명세서품목조회!G:G, "<="&(INT($B$4)-30)) -> 0 | N118: =MIN(L118, I118+J118) -> 0 | O118: =MIN(MAX(0, L118-N118), F118) -> 0 | P118: =MIN(MAX(0, L118-N118-O118), IFERROR(VLOOKUP(B118, '관리항목계정별잔액조회(전전월)'!$C:$E, 3, FALSE), 0)) -> 0 | Q118: =IF(H118=0, 0, MAX(0, L118-N118-O118-P118)) -> 0 | R118: =IF((COUNTIFS('관리항목계정별잔액조회(전월)'!$C:$C, B118, '관리항목계정별잔액조회(전월)'!$B:$B, "외화외상매출금") + COUNTIFS('관리항목계정별잔액조회(전전월)'!$C:$C, B118, '관리항목계정별잔액조회(전전월)'!$B:$B, "외화외상매출금")) > 0, "외화", "국내") -> 국내
B119: 명진약품 | C119: =IFERROR(VLOOKUP(B119,거래처별담당자!C:F,4,0), "#미등록") -> CSO팀 | D119: =IF(ISNUMBER(SEARCH("애터미_수출",B119)),"애터미_수출",IF(ISNUMBER(SEARCH("애터미",B119)),"애터미",IF(ISNUMBER(SEARCH("매나테크",B119)),"매나테크",IF(ISNUMBER(SEARCH("Mannatech, Incorporated",B119)),"매나테크",IFERROR(VLOOKUP(B119,거래처별담당자!C:F,3,0),"#미등록"))))) -> 김화니 | E119: =SUMIF('관리항목계정별잔액조회(전월)'!$C:$C,B119,'관리항목계정별잔액조회(전월)'!$D:$D) -> 0 | F119: =SUMIF('관리항목계정별잔액조회(전월)'!$C:$C,B119,'관리항목계정별잔액조회(전월)'!$E:$E) -> 453600 | G119: =SUMIF('관리항목계정별잔액조회(전월)'!$C:$C,B119,'관리항목계정별잔액조회(전월)'!$F:$F) -> 0 | H119: =SUMIF('관리항목계정별잔액조회(전월)'!$C:$C,B119,'관리항목계정별잔액조회(전월)'!$G:$G) -> 453600 | I119: =SUMIFS(거래명세서품목조회!BK:BK, 거래명세서품목조회!BX:BX, B119, 거래명세서품목조회!G:G, "<"&(EOMONTH($B$3, -1)+1))+SUMIFS(부서별전표작성조회!$I:$I,부서별전표작성조회!$AG:$AG,B119,부서별전표작성조회!$F:$F,"국내외상매출금",부서별전표작성조회!$V:$V,"") -> 0 | J119: =SUMIFS(거래명세서품목조회!AN:AN, 거래명세서품목조회!BX:BX, B119, 거래명세서품목조회!G:G, ">="&(EOMONTH($B$3, -1)+1), 거래명세서품목조회!G:G, "<="&EOMONTH($B$3, 0)) -> 0 | K119: =SUMIFS('입금다중입력(잔액기준)'!$O:$O, '입금다중입력(잔액기준)'!$E:$E, B119, '입금다중입력(잔액기준)'!$M:$M, "국내외상매출금") -> 0 | L119: =IFERROR(H119+I119+J119-K119,0) -> 453600 | M119: =SUMIFS(거래명세서품목조회!BK:BK, 거래명세서품목조회!BX:BX, B119, 거래명세서품목조회!G:G, "<="&(INT($B$4)-30)) -> 0 | N119: =MIN(L119, I119+J119) -> 0 | O119: =MIN(MAX(0, L119-N119), F119) -> 453600 | P119: 0 | Q119: =IF(H119=0, 0, MAX(0, L119-N119-O119-P119)) -> 0 | R119: =IF((COUNTIFS('관리항목계정별잔액조회(전월)'!$C:$C, B119, '관리항목계정별잔액조회(전월)'!$B:$B, "외화외상매출금") + COUNTIFS('관리항목계정별잔액조회(전전월)'!$C:$C, B119, '관리항목계정별잔액조회(전전월)'!$B:$B, "외화외상매출금")) > 0, "외화", "국내") -> 국내
B120: 명화약품 | C120: =IFERROR(VLOOKUP(B120,거래처별담당자!C:F,4,0), "#미등록") -> CSO팀 | D120: =IF(ISNUMBER(SEARCH("애터미_수출",B120)),"애터미_수출",IF(ISNUMBER(SEARCH("애터미",B120)),"애터미",IF(ISNUMBER(SEARCH("매나테크",B120)),"매나테크",IF(ISNUMBER(SEARCH("Mannatech, Incorporated",B120)),"매나테크",IFERROR(VLOOKUP(B120,거래처별담당자!C:F,3,0),"#미등록"))))) -> 김화니 | E120: =SUMIF('관리항목계정별잔액조회(전월)'!$C:$C,B120,'관리항목계정별잔액조회(전월)'!$D:$D) -> 4727700 | F120: =SUMIF('관리항목계정별잔액조회(전월)'!$C:$C,B120,'관리항목계정별잔액조회(전월)'!$E:$E) -> 0 | G120: =SUMIF('관리항목계정별잔액조회(전월)'!$C:$C,B120,'관리항목계정별잔액조회(전월)'!$F:$F) -> 4727700 | H120: =SUMIF('관리항목계정별잔액조회(전월)'!$C:$C,B120,'관리항목계정별잔액조회(전월)'!$G:$G) -> 0 | I120: =SUMIFS(거래명세서품목조회!BK:BK, 거래명세서품목조회!BX:BX, B120, 거래명세서품목조회!G:G, "<"&(EOMONTH($B$3, -1)+1))+SUMIFS(부서별전표작성조회!$I:$I,부서별전표작성조회!$AG:$AG,B120,부서별전표작성조회!$F:$F,"국내외상매출금",부서별전표작성조회!$V:$V,"") -> 0 | J120: =SUMIFS(거래명세서품목조회!AN:AN, 거래명세서품목조회!BX:BX, B120, 거래명세서품목조회!G:G, ">="&(EOMONTH($B$3, -1)+1), 거래명세서품목조회!G:G, "<="&EOMONTH($B$3, 0)) -> 0 | K120: =SUMIFS('입금다중입력(잔액기준)'!$O:$O, '입금다중입력(잔액기준)'!$E:$E, B120, '입금다중입력(잔액기준)'!$M:$M, "국내외상매출금") -> 0 | L120: =IFERROR(H120+I120+J120-K120,0) -> 0 | M120: =SUMIFS(거래명세서품목조회!BK:BK, 거래명세서품목조회!BX:BX, B120, 거래명세서품목조회!G:G, "<="&(INT($B$4)-30)) -> 0 | N120: =MIN(L120, I120+J120) -> 0 | O120: =MIN(MAX(0, L120-N120), F120) -> 0 | P120: =MIN(MAX(0, L120-N120-O120), IFERROR(VLOOKUP(B120, '관리항목계정별잔액조회(전전월)'!$C:$E, 3, FALSE), 0)) -> 0 | Q120: =IF(H120=0, 0, MAX(0, L120-N120-O120-P120)) -> 0 | R120: =IF((COUNTIFS('관리항목계정별잔액조회(전월)'!$C:$C, B120, '관리항목계정별잔액조회(전월)'!$B:$B, "외화외상매출금") + COUNTIFS('관리항목계정별잔액조회(전전월)'!$C:$C, B120, '관리항목계정별잔액조회(전전월)'!$B:$B, "외화외상매출금")) > 0, "외화", "국내") -> 국내
B121: 무지개약품 | C121: =IFERROR(VLOOKUP(B121,거래처별담당자!C:F,4,0), "#미등록") -> CSO팀 | D121: =IF(ISNUMBER(SEARCH("애터미_수출",B121)),"애터미_수출",IF(ISNUMBER(SEARCH("애터미",B121)),"애터미",IF(ISNUMBER(SEARCH("매나테크",B121)),"매나테크",IF(ISNUMBER(SEARCH("Mannatech, Incorporated",B121)),"매나테크",IFERROR(VLOOKUP(B121,거래처별담당자!C:F,3,0),"#미등록"))))) -> 김화니 | E121: =SUMIF('관리항목계정별잔액조회(전월)'!$C:$C,B121,'관리항목계정별잔액조회(전월)'!$D:$D) -> 0 | F121: =SUMIF('관리항목계정별잔액조회(전월)'!$C:$C,B121,'관리항목계정별잔액조회(전월)'!$E:$E) -> 857736 | G121: =SUMIF('관리항목계정별잔액조회(전월)'!$C:$C,B121,'관리항목계정별잔액조회(전월)'!$F:$F) -> 857736 | H121: =SUMIF('관리항목계정별잔액조회(전월)'!$C:$C,B121,'관리항목계정별잔액조회(전월)'!$G:$G) -> 0 | I121: =SUMIFS(거래명세서품목조회!BK:BK, 거래명세서품목조회!BX:BX, B121, 거래명세서품목조회!G:G, "<"&(EOMONTH($B$3, -1)+1))+SUMIFS(부서별전표작성조회!$I:$I,부서별전표작성조회!$AG:$AG,B121,부서별전표작성조회!$F:$F,"국내외상매출금",부서별전표작성조회!$V:$V,"") -> 0 | J121: =SUMIFS(거래명세서품목조회!AN:AN, 거래명세서품목조회!BX:BX, B121, 거래명세서품목조회!G:G, ">="&(EOMONTH($B$3, -1)+1), 거래명세서품목조회!G:G, "<="&EOMONTH($B$3, 0)) -> 0 | K121: =SUMIFS('입금다중입력(잔액기준)'!$O:$O, '입금다중입력(잔액기준)'!$E:$E, B121, '입금다중입력(잔액기준)'!$M:$M, "국내외상매출금") -> 0 | L121: =IFERROR(H121+I121+J121-K121,0) -> 0 | M121: =SUMIFS(거래명세서품목조회!BK:BK, 거래명세서품목조회!BX:BX, B121, 거래명세서품목조회!G:G, "<="&(INT($B$4)-30)) -> 0 | N121: =MIN(L121, I121+J121) -> 0 | O121: =MIN(MAX(0, L121-N121), F121) -> 0 | P121: 0 | Q121: =IF(H121=0, 0, MAX(0, L121-N121-O121-P121)) -> 0 | R121: =IF((COUNTIFS('관리항목계정별잔액조회(전월)'!$C:$C, B121, '관리항목계정별잔액조회(전월)'!$B:$B, "외화외상매출금") + COUNTIFS('관리항목계정별잔액조회(전전월)'!$C:$C, B121, '관리항목계정별잔액조회(전전월)'!$B:$B, "외화외상매출금")) > 0, "외화", "국내") -> 국내
B122: 미소팜 | C122: =IFERROR(VLOOKUP(B122,거래처별담당자!C:F,4,0), "#미등록") -> CSO팀 | D122: =IF(ISNUMBER(SEARCH("애터미_수출",B122)),"애터미_수출",IF(ISNUMBER(SEARCH("애터미",B122)),"애터미",IF(ISNUMBER(SEARCH("매나테크",B122)),"매나테크",IF(ISNUMBER(SEARCH("Mannatech, Incorporated",B122)),"매나테크",IFERROR(VLOOKUP(B122,거래처별담당자!C:F,3,0),"#미등록"))))) -> 김화니 | E122: =SUMIF('관리항목계정별잔액조회(전월)'!$C:$C,B122,'관리항목계정별잔액조회(전월)'!$D:$D) -> 0 | F122: =SUMIF('관리항목계정별잔액조회(전월)'!$C:$C,B122,'관리항목계정별잔액조회(전월)'!$E:$E) -> 276750 | G122: =SUMIF('관리항목계정별잔액조회(전월)'!$C:$C,B122,'관리항목계정별잔액조회(전월)'!$F:$F) -> 276750 | H122: =SUMIF('관리항목계정별잔액조회(전월)'!$C:$C,B122,'관리항목계정별잔액조회(전월)'!$G:$G) -> 0 | I122: =SUMIFS(거래명세서품목조회!BK:BK, 거래명세서품목조회!BX:BX, B122, 거래명세서품목조회!G:G, "<"&(EOMONTH($B$3, -1)+1))+SUMIFS(부서별전표작성조회!$I:$I,부서별전표작성조회!$AG:$AG,B122,부서별전표작성조회!$F:$F,"국내외상매출금",부서별전표작성조회!$V:$V,"") -> 0 | J122: =SUMIFS(거래명세서품목조회!AN:AN, 거래명세서품목조회!BX:BX, B122, 거래명세서품목조회!G:G, ">="&(EOMONTH($B$3, -1)+1), 거래명세서품목조회!G:G, "<="&EOMONTH($B$3, 0)) -> 0 | K122: =SUMIFS('입금다중입력(잔액기준)'!$O:$O, '입금다중입력(잔액기준)'!$E:$E, B122, '입금다중입력(잔액기준)'!$M:$M, "국내외상매출금") -> 0 | L122: =IFERROR(H122+I122+J122-K122,0) -> 0 | M122: =SUMIFS(거래명세서품목조회!BK:BK, 거래명세서품목조회!BX:BX, B122, 거래명세서품목조회!G:G, "<="&(INT($B$4)-30)) -> 0 | N122: =MIN(L122, I122+J122) -> 0 | O122: =MIN(MAX(0, L122-N122), F122) -> 0 | P122: =MIN(MAX(0, L122-N122-O122), IFERROR(VLOOKUP(B122, '관리항목계정별잔액조회(전전월)'!$C:$E, 3, FALSE), 0)) -> 0 | Q122: =IF(H122=0, 0, MAX(0, L122-N122-O122-P122)) -> 0 | R122: =IF((COUNTIFS('관리항목계정별잔액조회(전월)'!$C:$C, B122, '관리항목계정별잔액조회(전월)'!$B:$B, "외화외상매출금") + COUNTIFS('관리항목계정별잔액조회(전전월)'!$C:$C, B122, '관리항목계정별잔액조회(전전월)'!$B:$B, "외화외상매출금")) > 0, "외화", "국내") -> 국내
B123: 바다약국 | C123: =IFERROR(VLOOKUP(B123,거래처별담당자!C:F,4,0), "#미등록") -> OTC팀 | D123: =IF(ISNUMBER(SEARCH("애터미_수출",B123)),"애터미_수출",IF(ISNUMBER(SEARCH("애터미",B123)),"애터미",IF(ISNUMBER(SEARCH("매나테크",B123)),"매나테크",IF(ISNUMBER(SEARCH("Mannatech, Incorporated",B123)),"매나테크",IFERROR(VLOOKUP(B123,거래처별담당자!C:F,3,0),"#미등록"))))) -> 문혁표 | E123: =SUMIF('관리항목계정별잔액조회(전월)'!$C:$C,B123,'관리항목계정별잔액조회(전월)'!$D:$D) -> 0 | F123: =SUMIF('관리항목계정별잔액조회(전월)'!$C:$C,B123,'관리항목계정별잔액조회(전월)'!$E:$E) -> 0 | G123: =SUMIF('관리항목계정별잔액조회(전월)'!$C:$C,B123,'관리항목계정별잔액조회(전월)'!$F:$F) -> 0 | H123: =SUMIF('관리항목계정별잔액조회(전월)'!$C:$C,B123,'관리항목계정별잔액조회(전월)'!$G:$G) -> 0 | I123: =SUMIFS(거래명세서품목조회!BK:BK, 거래명세서품목조회!BX:BX, B123, 거래명세서품목조회!G:G, "<"&(EOMONTH($B$3, -1)+1))+SUMIFS(부서별전표작성조회!$I:$I,부서별전표작성조회!$AG:$AG,B123,부서별전표작성조회!$F:$F,"국내외상매출금",부서별전표작성조회!$V:$V,"") -> 0 | J123: =SUMIFS(거래명세서품목조회!AN:AN, 거래명세서품목조회!BX:BX, B123, 거래명세서품목조회!G:G, ">="&(EOMONTH($B$3, -1)+1), 거래명세서품목조회!G:G, "<="&EOMONTH($B$3, 0)) -> 0 | K123: =SUMIFS('입금다중입력(잔액기준)'!$O:$O, '입금다중입력(잔액기준)'!$E:$E, B123, '입금다중입력(잔액기준)'!$M:$M, "국내외상매출금") -> 0 | L123: =IFERROR(H123+I123+J123-K123,0) -> 0 | M123: =SUMIFS(거래명세서품목조회!BK:BK, 거래명세서품목조회!BX:BX, B123, 거래명세서품목조회!G:G, "<="&(INT($B$4)-30)) -> 0 | N123: =MIN(L123, I123+J123) -> 0 | O123: =MIN(MAX(0, L123-N123), F123) -> 0 | P123: =MIN(MAX(0, L123-N123-O123), IFERROR(VLOOKUP(B123, '관리항목계정별잔액조회(전전월)'!$C:$E, 3, FALSE), 0)) -> 0 | Q123: =IF(H123=0, 0, MAX(0, L123-N123-O123-P123)) -> 0 | R123: =IF((COUNTIFS('관리항목계정별잔액조회(전월)'!$C:$C, B123, '관리항목계정별잔액조회(전월)'!$B:$B, "외화외상매출금") + COUNTIFS('관리항목계정별잔액조회(전전월)'!$C:$C, B123, '관리항목계정별잔액조회(전전월)'!$B:$B, "외화외상매출금")) > 0, "외화", "국내") -> 국내
B124: 바른길약국 | C124: =IFERROR(VLOOKUP(B124,거래처별담당자!C:F,4,0), "#미등록") -> OTC팀 | D124: =IF(ISNUMBER(SEARCH("애터미_수출",B124)),"애터미_수출",IF(ISNUMBER(SEARCH("애터미",B124)),"애터미",IF(ISNUMBER(SEARCH("매나테크",B124)),"매나테크",IF(ISNUMBER(SEARCH("Mannatech, Incorporated",B124)),"매나테크",IFERROR(VLOOKUP(B124,거래처별담당자!C:F,3,0),"#미등록"))))) -> 이운범 | E124: =SUMIF('관리항목계정별잔액조회(전월)'!$C:$C,B124,'관리항목계정별잔액조회(전월)'!$D:$D) -> 0 | F124: =SUMIF('관리항목계정별잔액조회(전월)'!$C:$C,B124,'관리항목계정별잔액조회(전월)'!$E:$E) -> 48000 | G124: =SUMIF('관리항목계정별잔액조회(전월)'!$C:$C,B124,'관리항목계정별잔액조회(전월)'!$F:$F) -> 0 | H124: =SUMIF('관리항목계정별잔액조회(전월)'!$C:$C,B124,'관리항목계정별잔액조회(전월)'!$G:$G) -> 48000 | I124: =SUMIFS(거래명세서품목조회!BK:BK, 거래명세서품목조회!BX:BX, B124, 거래명세서품목조회!G:G, "<"&(EOMONTH($B$3, -1)+1))+SUMIFS(부서별전표작성조회!$I:$I,부서별전표작성조회!$AG:$AG,B124,부서별전표작성조회!$F:$F,"국내외상매출금",부서별전표작성조회!$V:$V,"") -> 0 | J124: =SUMIFS(거래명세서품목조회!AN:AN, 거래명세서품목조회!BX:BX, B124, 거래명세서품목조회!G:G, ">="&(EOMONTH($B$3, -1)+1), 거래명세서품목조회!G:G, "<="&EOMONTH($B$3, 0)) -> 0 | K124: =SUMIFS('입금다중입력(잔액기준)'!$O:$O, '입금다중입력(잔액기준)'!$E:$E, B124, '입금다중입력(잔액기준)'!$M:$M, "국내외상매출금") -> 45744 | L124: =IFERROR(H124+I124+J124-K124,0) -> 2256 | M124: =SUMIFS(거래명세서품목조회!BK:BK, 거래명세서품목조회!BX:BX, B124, 거래명세서품목조회!G:G, "<="&(INT($B$4)-30)) -> 0 | N124: =MIN(L124, I124+J124) -> 0 | O124: =MIN(MAX(0, L124-N124), F124) -> 2256 | P124: =MIN(MAX(0, L124-N124-O124), IFERROR(VLOOKUP(B124, '관리항목계정별잔액조회(전전월)'!$C:$E, 3, FALSE), 0)) -> 0 | Q124: =IF(H124=0, 0, MAX(0, L124-N124-O124-P124)) -> 0 | R124: =IF((COUNTIFS('관리항목계정별잔액조회(전월)'!$C:$C, B124, '관리항목계정별잔액조회(전월)'!$B:$B, "외화외상매출금") + COUNTIFS('관리항목계정별잔액조회(전전월)'!$C:$C, B124, '관리항목계정별잔액조회(전전월)'!$B:$B, "외화외상매출금")) > 0, "외화", "국내") -> 국내
B125: 백광의약품 | C125: =IFERROR(VLOOKUP(B125,거래처별담당자!C:F,4,0), "#미등록") -> CSO팀 | D125: =IF(ISNUMBER(SEARCH("애터미_수출",B125)),"애터미_수출",IF(ISNUMBER(SEARCH("애터미",B125)),"애터미",IF(ISNUMBER(SEARCH("매나테크",B125)),"매나테크",IF(ISNUMBER(SEARCH("Mannatech, Incorporated",B125)),"매나테크",IFERROR(VLOOKUP(B125,거래처별담당자!C:F,3,0),"#미등록"))))) -> 김화니 | E125: =SUMIF('관리항목계정별잔액조회(전월)'!$C:$C,B125,'관리항목계정별잔액조회(전월)'!$D:$D) -> -5282252 | F125: =SUMIF('관리항목계정별잔액조회(전월)'!$C:$C,B125,'관리항목계정별잔액조회(전월)'!$E:$E) -> 0 | G125: =SUMIF('관리항목계정별잔액조회(전월)'!$C:$C,B125,'관리항목계정별잔액조회(전월)'!$F:$F) -> 0 | H125: =SUMIF('관리항목계정별잔액조회(전월)'!$C:$C,B125,'관리항목계정별잔액조회(전월)'!$G:$G) -> -5282252 | I125: =SUMIFS(거래명세서품목조회!BK:BK, 거래명세서품목조회!BX:BX, B125, 거래명세서품목조회!G:G, "<"&(EOMONTH($B$3, -1)+1))+SUMIFS(부서별전표작성조회!$I:$I,부서별전표작성조회!$AG:$AG,B125,부서별전표작성조회!$F:$F,"국내외상매출금",부서별전표작성조회!$V:$V,"") -> 0 | J125: =SUMIFS(거래명세서품목조회!AN:AN, 거래명세서품목조회!BX:BX, B125, 거래명세서품목조회!G:G, ">="&(EOMONTH($B$3, -1)+1), 거래명세서품목조회!G:G, "<="&EOMONTH($B$3, 0)) -> 0 | K125: =SUMIFS('입금다중입력(잔액기준)'!$O:$O, '입금다중입력(잔액기준)'!$E:$E, B125, '입금다중입력(잔액기준)'!$M:$M, "국내외상매출금") -> 0 | L125: =IFERROR(H125+I125+J125-K125,0) -> -5282252 | M125: =SUMIFS(거래명세서품목조회!BK:BK, 거래명세서품목조회!BX:BX, B125, 거래명세서품목조회!G:G, "<="&(INT($B$4)-30)) -> 0 | N125: =MIN(L125, I125+J125) -> -5282252 | O125: =MIN(MAX(0, L125-N125), F125) -> 0 | P125: =MIN(MAX(0, L125-N125-O125), IFERROR(VLOOKUP(B125, '관리항목계정별잔액조회(전전월)'!$C:$E, 3, FALSE), 0)) -> 0 | Q125: =IF(H125=0, 0, MAX(0, L125-N125-O125-P125)) -> 0 | R125: =IF((COUNTIFS('관리항목계정별잔액조회(전월)'!$C:$C, B125, '관리항목계정별잔액조회(전월)'!$B:$B, "외화외상매출금") + COUNTIFS('관리항목계정별잔액조회(전전월)'!$C:$C, B125, '관리항목계정별잔액조회(전전월)'!$B:$B, "외화외상매출금")) > 0, "외화", "국내") -> 국내
B126: 백제약품대전지점(OTC) | C126: =IFERROR(VLOOKUP(B126,거래처별담당자!C:F,4,0), "#미등록") -> OTC팀 | D126: =IF(ISNUMBER(SEARCH("애터미_수출",B126)),"애터미_수출",IF(ISNUMBER(SEARCH("애터미",B126)),"애터미",IF(ISNUMBER(SEARCH("매나테크",B126)),"매나테크",IF(ISNUMBER(SEARCH("Mannatech, Incorporated",B126)),"매나테크",IFERROR(VLOOKUP(B126,거래처별담당자!C:F,3,0),"#미등록"))))) -> 문혁표 | E126: =SUMIF('관리항목계정별잔액조회(전월)'!$C:$C,B126,'관리항목계정별잔액조회(전월)'!$D:$D) -> 0 | F126: =SUMIF('관리항목계정별잔액조회(전월)'!$C:$C,B126,'관리항목계정별잔액조회(전월)'!$E:$E) -> -12100 | G126: =SUMIF('관리항목계정별잔액조회(전월)'!$C:$C,B126,'관리항목계정별잔액조회(전월)'!$F:$F) -> 0 | H126: =SUMIF('관리항목계정별잔액조회(전월)'!$C:$C,B126,'관리항목계정별잔액조회(전월)'!$G:$G) -> -12100 | I126: =SUMIFS(거래명세서품목조회!BK:BK, 거래명세서품목조회!BX:BX, B126, 거래명세서품목조회!G:G, "<"&(EOMONTH($B$3, -1)+1))+SUMIFS(부서별전표작성조회!$I:$I,부서별전표작성조회!$AG:$AG,B126,부서별전표작성조회!$F:$F,"국내외상매출금",부서별전표작성조회!$V:$V,"") -> 0 | J126: =SUMIFS(거래명세서품목조회!AN:AN, 거래명세서품목조회!BX:BX, B126, 거래명세서품목조회!G:G, ">="&(EOMONTH($B$3, -1)+1), 거래명세서품목조회!G:G, "<="&EOMONTH($B$3, 0)) -> 0 | K126: =SUMIFS('입금다중입력(잔액기준)'!$O:$O, '입금다중입력(잔액기준)'!$E:$E, B126, '입금다중입력(잔액기준)'!$M:$M, "국내외상매출금") -> 0 | L126: =IFERROR(H126+I126+J126-K126,0) -> -12100 | M126: =SUMIFS(거래명세서품목조회!BK:BK, 거래명세서품목조회!BX:BX, B126, 거래명세서품목조회!G:G, "<="&(INT($B$4)-30)) -> 0 | N126: =MIN(L126, I126+J126) -> -12100 | O126: =MIN(MAX(0, L126-N126), F126) -> -12100 | P126: =MIN(MAX(0, L126-N126-O126), IFERROR(VLOOKUP(B126, '관리항목계정별잔액조회(전전월)'!$C:$E, 3, FALSE), 0)) -> 0 | Q126: =IF(H126=0, 0, MAX(0, L126-N126-O126-P126)) -> 12100 | R126: =IF((COUNTIFS('관리항목계정별잔액조회(전월)'!$C:$C, B126, '관리항목계정별잔액조회(전월)'!$B:$B, "외화외상매출금") + COUNTIFS('관리항목계정별잔액조회(전전월)'!$C:$C, B126, '관리항목계정별잔액조회(전전월)'!$B:$B, "외화외상매출금")) > 0, "외화", "국내") -> 국내
B127: 백제약품영남본부(OTC) | C127: =IFERROR(VLOOKUP(B127,거래처별담당자!C:F,4,0), "#미등록") -> OTC팀 | D127: =IF(ISNUMBER(SEARCH("애터미_수출",B127)),"애터미_수출",IF(ISNUMBER(SEARCH("애터미",B127)),"애터미",IF(ISNUMBER(SEARCH("매나테크",B127)),"매나테크",IF(ISNUMBER(SEARCH("Mannatech, Incorporated",B127)),"매나테크",IFERROR(VLOOKUP(B127,거래처별담당자!C:F,3,0),"#미등록"))))) -> 문혁표 | E127: =SUMIF('관리항목계정별잔액조회(전월)'!$C:$C,B127,'관리항목계정별잔액조회(전월)'!$D:$D) -> -653400 | F127: =SUMIF('관리항목계정별잔액조회(전월)'!$C:$C,B127,'관리항목계정별잔액조회(전월)'!$E:$E) -> 0 | G127: =SUMIF('관리항목계정별잔액조회(전월)'!$C:$C,B127,'관리항목계정별잔액조회(전월)'!$F:$F) -> 0 | H127: =SUMIF('관리항목계정별잔액조회(전월)'!$C:$C,B127,'관리항목계정별잔액조회(전월)'!$G:$G) -> -653400 | I127: =SUMIFS(거래명세서품목조회!BK:BK, 거래명세서품목조회!BX:BX, B127, 거래명세서품목조회!G:G, "<"&(EOMONTH($B$3, -1)+1))+SUMIFS(부서별전표작성조회!$I:$I,부서별전표작성조회!$AG:$AG,B127,부서별전표작성조회!$F:$F,"국내외상매출금",부서별전표작성조회!$V:$V,"") -> 0 | J127: =SUMIFS(거래명세서품목조회!AN:AN, 거래명세서품목조회!BX:BX, B127, 거래명세서품목조회!G:G, ">="&(EOMONTH($B$3, -1)+1), 거래명세서품목조회!G:G, "<="&EOMONTH($B$3, 0)) -> 0 | K127: =SUMIFS('입금다중입력(잔액기준)'!$O:$O, '입금다중입력(잔액기준)'!$E:$E, B127, '입금다중입력(잔액기준)'!$M:$M, "국내외상매출금") -> 0 | L127: =IFERROR(H127+I127+J127-K127,0) -> -653400 | M127: =SUMIFS(거래명세서품목조회!BK:BK, 거래명세서품목조회!BX:BX, B127, 거래명세서품목조회!G:G, "<="&(INT($B$4)-30)) -> 0 | N127: =MIN(L127, I127+J127) -> -653400 | O127: =MIN(MAX(0, L127-N127), F127) -> 0 | P127: =MIN(MAX(0, L127-N127-O127), IFERROR(VLOOKUP(B127, '관리항목계정별잔액조회(전전월)'!$C:$E, 3, FALSE), 0)) -> 0 | Q127: =IF(H127=0, 0, MAX(0, L127-N127-O127-P127)) -> 0 | R127: =IF((COUNTIFS('관리항목계정별잔액조회(전월)'!$C:$C, B127, '관리항목계정별잔액조회(전월)'!$B:$B, "외화외상매출금") + COUNTIFS('관리항목계정별잔액조회(전전월)'!$C:$C, B127, '관리항목계정별잔액조회(전전월)'!$B:$B, "외화외상매출금")) > 0, "외화", "국내") -> 국내
B128: 백제약품영등포지점(OTC) | C128: =IFERROR(VLOOKUP(B128,거래처별담당자!C:F,4,0), "#미등록") -> OTC팀 | D128: =IF(ISNUMBER(SEARCH("애터미_수출",B128)),"애터미_수출",IF(ISNUMBER(SEARCH("애터미",B128)),"애터미",IF(ISNUMBER(SEARCH("매나테크",B128)),"매나테크",IF(ISNUMBER(SEARCH("Mannatech, Incorporated",B128)),"매나테크",IFERROR(VLOOKUP(B128,거래처별담당자!C:F,3,0),"#미등록"))))) -> 문혁표 | E128: =SUMIF('관리항목계정별잔액조회(전월)'!$C:$C,B128,'관리항목계정별잔액조회(전월)'!$D:$D) -> -10422940 | F128: =SUMIF('관리항목계정별잔액조회(전월)'!$C:$C,B128,'관리항목계정별잔액조회(전월)'!$E:$E) -> 0 | G128: =SUMIF('관리항목계정별잔액조회(전월)'!$C:$C,B128,'관리항목계정별잔액조회(전월)'!$F:$F) -> 0 | H128: =SUMIF('관리항목계정별잔액조회(전월)'!$C:$C,B128,'관리항목계정별잔액조회(전월)'!$G:$G) -> -10422940 | I128: =SUMIFS(거래명세서품목조회!BK:BK, 거래명세서품목조회!BX:BX, B128, 거래명세서품목조회!G:G, "<"&(EOMONTH($B$3, -1)+1))+SUMIFS(부서별전표작성조회!$I:$I,부서별전표작성조회!$AG:$AG,B128,부서별전표작성조회!$F:$F,"국내외상매출금",부서별전표작성조회!$V:$V,"") -> 0 | J128: =SUMIFS(거래명세서품목조회!AN:AN, 거래명세서품목조회!BX:BX, B128, 거래명세서품목조회!G:G, ">="&(EOMONTH($B$3, -1)+1), 거래명세서품목조회!G:G, "<="&EOMONTH($B$3, 0)) -> 0 | K128: =SUMIFS('입금다중입력(잔액기준)'!$O:$O, '입금다중입력(잔액기준)'!$E:$E, B128, '입금다중입력(잔액기준)'!$M:$M, "국내외상매출금") -> 0 | L128: =IFERROR(H128+I128+J128-K128,0) -> -10422940 | M128: =SUMIFS(거래명세서품목조회!BK:BK, 거래명세서품목조회!BX:BX, B128, 거래명세서품목조회!G:G, "<="&(INT($B$4)-30)) -> 0 | N128: =MIN(L128, I128+J128) -> -10422940 | O128: =MIN(MAX(0, L128-N128), F128) -> 0 | P128: =MIN(MAX(0, L128-N128-O128), IFERROR(VLOOKUP(B128, '관리항목계정별잔액조회(전전월)'!$C:$E, 3, FALSE), 0)) -> -125840 | Q128: =IF(H128=0, 0, MAX(0, L128-N128-O128-P128)) -> 125840 | R128: =IF((COUNTIFS('관리항목계정별잔액조회(전월)'!$C:$C, B128, '관리항목계정별잔액조회(전월)'!$B:$B, "외화외상매출금") + COUNTIFS('관리항목계정별잔액조회(전전월)'!$C:$C, B128, '관리항목계정별잔액조회(전전월)'!$B:$B, "외화외상매출금")) > 0, "외화", "국내") -> 국내
B129: 베리언스 | C129: =IFERROR(VLOOKUP(B129,거래처별담당자!C:F,4,0), "#미등록") -> CSO팀 | D129: =IF(ISNUMBER(SEARCH("애터미_수출",B129)),"애터미_수출",IF(ISNUMBER(SEARCH("애터미",B129)),"애터미",IF(ISNUMBER(SEARCH("매나테크",B129)),"매나테크",IF(ISNUMBER(SEARCH("Mannatech, Incorporated",B129)),"매나테크",IFERROR(VLOOKUP(B129,거래처별담당자!C:F,3,0),"#미등록"))))) -> 김화니 | E129: =SUMIF('관리항목계정별잔액조회(전월)'!$C:$C,B129,'관리항목계정별잔액조회(전월)'!$D:$D) -> 0 | F129: =SUMIF('관리항목계정별잔액조회(전월)'!$C:$C,B129,'관리항목계정별잔액조회(전월)'!$E:$E) -> 0 | G129: =SUMIF('관리항목계정별잔액조회(전월)'!$C:$C,B129,'관리항목계정별잔액조회(전월)'!$F:$F) -> 0 | H129: =SUMIF('관리항목계정별잔액조회(전월)'!$C:$C,B129,'관리항목계정별잔액조회(전월)'!$G:$G) -> 0 | I129: =SUMIFS(거래명세서품목조회!BK:BK, 거래명세서품목조회!BX:BX, B129, 거래명세서품목조회!G:G, "<"&(EOMONTH($B$3, -1)+1))+SUMIFS(부서별전표작성조회!$I:$I,부서별전표작성조회!$AG:$AG,B129,부서별전표작성조회!$F:$F,"국내외상매출금",부서별전표작성조회!$V:$V,"") -> 0 | J129: =SUMIFS(거래명세서품목조회!AN:AN, 거래명세서품목조회!BX:BX, B129, 거래명세서품목조회!G:G, ">="&(EOMONTH($B$3, -1)+1), 거래명세서품목조회!G:G, "<="&EOMONTH($B$3, 0)) -> 0 | K129: =SUMIFS('입금다중입력(잔액기준)'!$O:$O, '입금다중입력(잔액기준)'!$E:$E, B129, '입금다중입력(잔액기준)'!$M:$M, "국내외상매출금") -> 0 | L129: =IFERROR(H129+I129+J129-K129,0) -> 0 | M129: =SUMIFS(거래명세서품목조회!BK:BK, 거래명세서품목조회!BX:BX, B129, 거래명세서품목조회!G:G, "<="&(INT($B$4)-30)) -> 0 | N129: =MIN(L129, I129+J129) -> 0 | O129: =MIN(MAX(0, L129-N129), F129) -> 0 | P129: =MIN(MAX(0, L129-N129-O129), IFERROR(VLOOKUP(B129, '관리항목계정별잔액조회(전전월)'!$C:$E, 3, FALSE), 0)) -> 0 | Q129: =IF(H129=0, 0, MAX(0, L129-N129-O129-P129)) -> 0 | R129: =IF((COUNTIFS('관리항목계정별잔액조회(전월)'!$C:$C, B129, '관리항목계정별잔액조회(전월)'!$B:$B, "외화외상매출금") + COUNTIFS('관리항목계정별잔액조회(전전월)'!$C:$C, B129, '관리항목계정별잔액조회(전전월)'!$B:$B, "외화외상매출금")) > 0, "외화", "국내") -> 국내
B130: 베스트팜 | C130: =IFERROR(VLOOKUP(B130,거래처별담당자!C:F,4,0), "#미등록") -> CSO팀 | D130: =IF(ISNUMBER(SEARCH("애터미_수출",B130)),"애터미_수출",IF(ISNUMBER(SEARCH("애터미",B130)),"애터미",IF(ISNUMBER(SEARCH("매나테크",B130)),"매나테크",IF(ISNUMBER(SEARCH("Mannatech, Incorporated",B130)),"매나테크",IFERROR(VLOOKUP(B130,거래처별담당자!C:F,3,0),"#미등록"))))) -> 김화니 | E130: =SUMIF('관리항목계정별잔액조회(전월)'!$C:$C,B130,'관리항목계정별잔액조회(전월)'!$D:$D) -> 1106998 | F130: =SUMIF('관리항목계정별잔액조회(전월)'!$C:$C,B130,'관리항목계정별잔액조회(전월)'!$E:$E) -> 476280 | G130: =SUMIF('관리항목계정별잔액조회(전월)'!$C:$C,B130,'관리항목계정별잔액조회(전월)'!$F:$F) -> 1107000 | H130: =SUMIF('관리항목계정별잔액조회(전월)'!$C:$C,B130,'관리항목계정별잔액조회(전월)'!$G:$G) -> 476278 | I130: =SUMIFS(거래명세서품목조회!BK:BK, 거래명세서품목조회!BX:BX, B130, 거래명세서품목조회!G:G, "<"&(EOMONTH($B$3, -1)+1))+SUMIFS(부서별전표작성조회!$I:$I,부서별전표작성조회!$AG:$AG,B130,부서별전표작성조회!$F:$F,"국내외상매출금",부서별전표작성조회!$V:$V,"") -> 0 | J130: =SUMIFS(거래명세서품목조회!AN:AN, 거래명세서품목조회!BX:BX, B130, 거래명세서품목조회!G:G, ">="&(EOMONTH($B$3, -1)+1), 거래명세서품목조회!G:G, "<="&EOMONTH($B$3, 0)) -> 0 | K130: =SUMIFS('입금다중입력(잔액기준)'!$O:$O, '입금다중입력(잔액기준)'!$E:$E, B130, '입금다중입력(잔액기준)'!$M:$M, "국내외상매출금") -> 0 | L130: =IFERROR(H130+I130+J130-K130,0) -> 476278 | M130: =SUMIFS(거래명세서품목조회!BK:BK, 거래명세서품목조회!BX:BX, B130, 거래명세서품목조회!G:G, "<="&(INT($B$4)-30)) -> 0 | N130: =MIN(L130, I130+J130) -> 0 | O130: =MIN(MAX(0, L130-N130), F130) -> 476278 | P130: =MIN(MAX(0, L130-N130-O130), IFERROR(VLOOKUP(B130, '관리항목계정별잔액조회(전전월)'!$C:$E, 3, FALSE), 0)) -> 0 | Q130: =IF(H130=0, 0, MAX(0, L130-N130-O130-P130)) -> 0 | R130: =IF((COUNTIFS('관리항목계정별잔액조회(전월)'!$C:$C, B130, '관리항목계정별잔액조회(전월)'!$B:$B, "외화외상매출금") + COUNTIFS('관리항목계정별잔액조회(전전월)'!$C:$C, B130, '관리항목계정별잔액조회(전전월)'!$B:$B, "외화외상매출금")) > 0, "외화", "국내") -> 국내
B131: 보덕메디팜(OTC) | C131: =IFERROR(VLOOKUP(B131,거래처별담당자!C:F,4,0), "#미등록") -> OTC팀 | D131: =IF(ISNUMBER(SEARCH("애터미_수출",B131)),"애터미_수출",IF(ISNUMBER(SEARCH("애터미",B131)),"애터미",IF(ISNUMBER(SEARCH("매나테크",B131)),"매나테크",IF(ISNUMBER(SEARCH("Mannatech, Incorporated",B131)),"매나테크",IFERROR(VLOOKUP(B131,거래처별담당자!C:F,3,0),"#미등록"))))) -> 문혁표 | E131: =SUMIF('관리항목계정별잔액조회(전월)'!$C:$C,B131,'관리항목계정별잔액조회(전월)'!$D:$D) -> -1808980 | F131: =SUMIF('관리항목계정별잔액조회(전월)'!$C:$C,B131,'관리항목계정별잔액조회(전월)'!$E:$E) -> 0 | G131: =SUMIF('관리항목계정별잔액조회(전월)'!$C:$C,B131,'관리항목계정별잔액조회(전월)'!$F:$F) -> 0 | H131: =SUMIF('관리항목계정별잔액조회(전월)'!$C:$C,B131,'관리항목계정별잔액조회(전월)'!$G:$G) -> -1808980 | I131: =SUMIFS(거래명세서품목조회!BK:BK, 거래명세서품목조회!BX:BX, B131, 거래명세서품목조회!G:G, "<"&(EOMONTH($B$3, -1)+1))+SUMIFS(부서별전표작성조회!$I:$I,부서별전표작성조회!$AG:$AG,B131,부서별전표작성조회!$F:$F,"국내외상매출금",부서별전표작성조회!$V:$V,"") -> 0 | J131: =SUMIFS(거래명세서품목조회!AN:AN, 거래명세서품목조회!BX:BX, B131, 거래명세서품목조회!G:G, ">="&(EOMONTH($B$3, -1)+1), 거래명세서품목조회!G:G, "<="&EOMONTH($B$3, 0)) -> 0 | K131: =SUMIFS('입금다중입력(잔액기준)'!$O:$O, '입금다중입력(잔액기준)'!$E:$E, B131, '입금다중입력(잔액기준)'!$M:$M, "국내외상매출금") -> 0 | L131: =IFERROR(H131+I131+J131-K131,0) -> -1808980 | M131: =SUMIFS(거래명세서품목조회!BK:BK, 거래명세서품목조회!BX:BX, B131, 거래명세서품목조회!G:G, "<="&(INT($B$4)-30)) -> 0 | N131: =MIN(L131, I131+J131) -> -1808980 | O131: =MIN(MAX(0, L131-N131), F131) -> 0 | P131: =MIN(MAX(0, L131-N131-O131), IFERROR(VLOOKUP(B131, '관리항목계정별잔액조회(전전월)'!$C:$E, 3, FALSE), 0)) -> 0 | Q131: =IF(H131=0, 0, MAX(0, L131-N131-O131-P131)) -> 0 | R131: =IF((COUNTIFS('관리항목계정별잔액조회(전월)'!$C:$C, B131, '관리항목계정별잔액조회(전월)'!$B:$B, "외화외상매출금") + COUNTIFS('관리항목계정별잔액조회(전전월)'!$C:$C, B131, '관리항목계정별잔액조회(전전월)'!$B:$B, "외화외상매출금")) > 0, "외화", "국내") -> 국내
B132: 복산나이스(OTC) | C132: =IFERROR(VLOOKUP(B132,거래처별담당자!C:F,4,0), "#미등록") -> OTC팀 | D132: =IF(ISNUMBER(SEARCH("애터미_수출",B132)),"애터미_수출",IF(ISNUMBER(SEARCH("애터미",B132)),"애터미",IF(ISNUMBER(SEARCH("매나테크",B132)),"매나테크",IF(ISNUMBER(SEARCH("Mannatech, Incorporated",B132)),"매나테크",IFERROR(VLOOKUP(B132,거래처별담당자!C:F,3,0),"#미등록"))))) -> 문혁표 | E132: =SUMIF('관리항목계정별잔액조회(전월)'!$C:$C,B132,'관리항목계정별잔액조회(전월)'!$D:$D) -> -1714300 | F132: =SUMIF('관리항목계정별잔액조회(전월)'!$C:$C,B132,'관리항목계정별잔액조회(전월)'!$E:$E) -> 0 | G132: =SUMIF('관리항목계정별잔액조회(전월)'!$C:$C,B132,'관리항목계정별잔액조회(전월)'!$F:$F) -> 0 | H132: =SUMIF('관리항목계정별잔액조회(전월)'!$C:$C,B132,'관리항목계정별잔액조회(전월)'!$G:$G) -> -1714300 | I132: =SUMIFS(거래명세서품목조회!BK:BK, 거래명세서품목조회!BX:BX, B132, 거래명세서품목조회!G:G, "<"&(EOMONTH($B$3, -1)+1))+SUMIFS(부서별전표작성조회!$I:$I,부서별전표작성조회!$AG:$AG,B132,부서별전표작성조회!$F:$F,"국내외상매출금",부서별전표작성조회!$V:$V,"") -> 0 | J132: =SUMIFS(거래명세서품목조회!AN:AN, 거래명세서품목조회!BX:BX, B132, 거래명세서품목조회!G:G, ">="&(EOMONTH($B$3, -1)+1), 거래명세서품목조회!G:G, "<="&EOMONTH($B$3, 0)) -> 0 | K132: =SUMIFS('입금다중입력(잔액기준)'!$O:$O, '입금다중입력(잔액기준)'!$E:$E, B132, '입금다중입력(잔액기준)'!$M:$M, "국내외상매출금") -> 0 | L132: =IFERROR(H132+I132+J132-K132,0) -> -1714300 | M132: =SUMIFS(거래명세서품목조회!BK:BK, 거래명세서품목조회!BX:BX, B132, 거래명세서품목조회!G:G, "<="&(INT($B$4)-30)) -> 0 | N132: =MIN(L132, I132+J132) -> -1714300 | O132: =MIN(MAX(0, L132-N132), F132) -> 0 | P132: =MIN(MAX(0, L132-N132-O132), IFERROR(VLOOKUP(B132, '관리항목계정별잔액조회(전전월)'!$C:$E, 3, FALSE), 0)) -> 0 | Q132: =IF(H132=0, 0, MAX(0, L132-N132-O132-P132)) -> 0 | R132: =IF((COUNTIFS('관리항목계정별잔액조회(전월)'!$C:$C, B132, '관리항목계정별잔액조회(전월)'!$B:$B, "외화외상매출금") + COUNTIFS('관리항목계정별잔액조회(전전월)'!$C:$C, B132, '관리항목계정별잔액조회(전전월)'!$B:$B, "외화외상매출금")) > 0, "외화", "국내") -> 국내
B133: 부림약품 | C133: =IFERROR(VLOOKUP(B133,거래처별담당자!C:F,4,0), "#미등록") -> CSO팀 | D133: =IF(ISNUMBER(SEARCH("애터미_수출",B133)),"애터미_수출",IF(ISNUMBER(SEARCH("애터미",B133)),"애터미",IF(ISNUMBER(SEARCH("매나테크",B133)),"매나테크",IF(ISNUMBER(SEARCH("Mannatech, Incorporated",B133)),"매나테크",IFERROR(VLOOKUP(B133,거래처별담당자!C:F,3,0),"#미등록"))))) -> 김화니 | E133: =SUMIF('관리항목계정별잔액조회(전월)'!$C:$C,B133,'관리항목계정별잔액조회(전월)'!$D:$D) -> 0 | F133: =SUMIF('관리항목계정별잔액조회(전월)'!$C:$C,B133,'관리항목계정별잔액조회(전월)'!$E:$E) -> 0 | G133: =SUMIF('관리항목계정별잔액조회(전월)'!$C:$C,B133,'관리항목계정별잔액조회(전월)'!$F:$F) -> 0 | H133: =SUMIF('관리항목계정별잔액조회(전월)'!$C:$C,B133,'관리항목계정별잔액조회(전월)'!$G:$G) -> 0 | I133: =SUMIFS(거래명세서품목조회!BK:BK, 거래명세서품목조회!BX:BX, B133, 거래명세서품목조회!G:G, "<"&(EOMONTH($B$3, -1)+1))+SUMIFS(부서별전표작성조회!$I:$I,부서별전표작성조회!$AG:$AG,B133,부서별전표작성조회!$F:$F,"국내외상매출금",부서별전표작성조회!$V:$V,"") -> 0 | J133: =SUMIFS(거래명세서품목조회!AN:AN, 거래명세서품목조회!BX:BX, B133, 거래명세서품목조회!G:G, ">="&(EOMONTH($B$3, -1)+1), 거래명세서품목조회!G:G, "<="&EOMONTH($B$3, 0)) -> 0 | K133: =SUMIFS('입금다중입력(잔액기준)'!$O:$O, '입금다중입력(잔액기준)'!$E:$E, B133, '입금다중입력(잔액기준)'!$M:$M, "국내외상매출금") -> 0 | L133: =IFERROR(H133+I133+J133-K133,0) -> 0 | M133: =SUMIFS(거래명세서품목조회!BK:BK, 거래명세서품목조회!BX:BX, B133, 거래명세서품목조회!G:G, "<="&(INT($B$4)-30)) -> 0 | N133: =MIN(L133, I133+J133) -> 0 | O133: =MIN(MAX(0, L133-N133), F133) -> 0 | P133: =MIN(MAX(0, L133-N133-O133), IFERROR(VLOOKUP(B133, '관리항목계정별잔액조회(전전월)'!$C:$E, 3, FALSE), 0)) -> 0 | Q133: =IF(H133=0, 0, MAX(0, L133-N133-O133-P133)) -> 0 | R133: =IF((COUNTIFS('관리항목계정별잔액조회(전월)'!$C:$C, B133, '관리항목계정별잔액조회(전월)'!$B:$B, "외화외상매출금") + COUNTIFS('관리항목계정별잔액조회(전전월)'!$C:$C, B133, '관리항목계정별잔액조회(전전월)'!$B:$B, "외화외상매출금")) > 0, "외화", "국내") -> 국내
... B223: 히스토바이오 | C223: =IFERROR(VLOOKUP(B223,거래처별담당자!C:F,4,0), "#미등록") -> CSO팀 | D223: =IF(ISNUMBER(SEARCH("애터미_수출",B223)),"애터미_수출",IF(ISNUMBER(SEARCH("애터미",B223)),"애터미",IF(ISNUMBER(SEARCH("매나테크",B223)),"매나테크",IF(ISNUMBER(SEARCH("Mannatech, Incorporated",B223)),"매나테크",IFERROR(VLOOKUP(B223,거래처별담당자!C:F,3,0),"#미등록"))))) -> 김화니 | E223: =SUMIF('관리항목계정별잔액조회(전월)'!$C:$C,B223,'관리항목계정별잔액조회(전월)'!$D:$D) -> 0 | F223: =SUMIF('관리항목계정별잔액조회(전월)'!$C:$C,B223,'관리항목계정별잔액조회(전월)'!$E:$E) -> 0 | G223: =SUMIF('관리항목계정별잔액조회(전월)'!$C:$C,B223,'관리항목계정별잔액조회(전월)'!$F:$F) -> 0 | H223: =SUMIF('관리항목계정별잔액조회(전월)'!$C:$C,B223,'관리항목계정별잔액조회(전월)'!$G:$G) -> 0 | I223: =SUMIFS(거래명세서품목조회!BK:BK, 거래명세서품목조회!BX:BX, B223, 거래명세서품목조회!G:G, "<"&(EOMONTH($B$3, -1)+1))+SUMIFS(부서별전표작성조회!$I:$I,부서별전표작성조회!$AG:$AG,B223,부서별전표작성조회!$F:$F,"국내외상매출금",부서별전표작성조회!$V:$V,"") -> 0 | J223: =SUMIFS(거래명세서품목조회!AN:AN, 거래명세서품목조회!BX:BX, B223, 거래명세서품목조회!G:G, ">="&(EOMONTH($B$3, -1)+1), 거래명세서품목조회!G:G, "<="&EOMONTH($B$3, 0)) -> 0 | K223: =SUMIFS('입금다중입력(잔액기준)'!$O:$O, '입금다중입력(잔액기준)'!$E:$E, B223, '입금다중입력(잔액기준)'!$M:$M, "국내외상매출금") -> 0 | L223: =IFERROR(H223+I223+J223-K223,0) -> 0 | M223: =SUMIFS(거래명세서품목조회!BK:BK, 거래명세서품목조회!BX:BX, B223, 거래명세서품목조회!G:G, "<="&(INT($B$4)-30)) -> 0 | N223: =MIN(L223, I223+J223) -> 0 | O223: =MIN(MAX(0, L223-N223), F223) -> 0 | P223: =MIN(MAX(0, L223-N223-O223), IFERROR(VLOOKUP(B223, '관리항목계정별잔액조회(전전월)'!$C:$E, 3, FALSE), 0)) -> 0 | Q223: =IF(H223=0, 0, MAX(0, L223-N223-O223-P223)) -> 0 | R223: =IF((COUNTIFS('관리항목계정별잔액조회(전월)'!$C:$C, B223, '관리항목계정별잔액조회(전월)'!$B:$B, "외화외상매출금") + COUNTIFS('관리항목계정별잔액조회(전전월)'!$C:$C, B223, '관리항목계정별잔액조회(전전월)'!$B:$B, "외화외상매출금")) > 0, "외화", "국내") -> 국내
C224: =IFERROR(VLOOKUP(B224,거래처별담당자!C:F,4,0), "#미등록") -> #미등록 | D224: =IF(ISNUMBER(SEARCH("애터미_수출",B224)),"애터미_수출",IF(ISNUMBER(SEARCH("애터미",B224)),"애터미",IF(ISNUMBER(SEARCH("매나테크",B224)),"매나테크",IF(ISNUMBER(SEARCH("Mannatech, Incorporated",B224)),"매나테크",IFERROR(VLOOKUP(B224,거래처별담당자!C:F,3,0),"#미등록"))))) -> #미등록 | E224: =SUMIF('관리항목계정별잔액조회(전월)'!$C:$C,B224,'관리항목계정별잔액조회(전월)'!$D:$D) -> 0 | F224: =SUMIF('관리항목계정별잔액조회(전월)'!$C:$C,B224,'관리항목계정별잔액조회(전월)'!$E:$E) -> 0 | G224: =SUMIF('관리항목계정별잔액조회(전월)'!$C:$C,B224,'관리항목계정별잔액조회(전월)'!$F:$F) -> 0 | H224: =SUMIF('관리항목계정별잔액조회(전월)'!$C:$C,B224,'관리항목계정별잔액조회(전월)'!$G:$G) -> 0 | I224: =SUMIFS(거래명세서품목조회!BK:BK, 거래명세서품목조회!BX:BX, B224, 거래명세서품목조회!G:G, "<"&(EOMONTH($B$3, -1)+1))+SUMIFS(부서별전표작성조회!$I:$I,부서별전표작성조회!$AG:$AG,B224,부서별전표작성조회!$F:$F,"국내외상매출금",부서별전표작성조회!$V:$V,"") -> 0 | J224: =SUMIFS(거래명세서품목조회!AN:AN, 거래명세서품목조회!BX:BX, B224, 거래명세서품목조회!G:G, ">="&(EOMONTH($B$3, -1)+1), 거래명세서품목조회!G:G, "<="&EOMONTH($B$3, 0)) -> 0 | K224: =SUMIFS('입금다중입력(잔액기준)'!$O:$O, '입금다중입력(잔액기준)'!$E:$E, B224, '입금다중입력(잔액기준)'!$M:$M, "국내외상매출금") -> 0 | L224: =IFERROR(H224+I224+J224-K224,0) -> 0 | M224: =SUMIFS(거래명세서품목조회!BK:BK, 거래명세서품목조회!BX:BX, B224, 거래명세서품목조회!G:G, "<="&(INT($B$4)-30)) -> 0 | N224: =MIN(L224, I224+J224) -> 0 | O224: =MIN(MAX(0, L224-N224), F224) -> 0 | P224: =MIN(MAX(0, L224-N224-O224), IFERROR(VLOOKUP(B224, '관리항목계정별잔액조회(전전월)'!$C:$E, 3, FALSE), 0)) -> 0 | Q224: =IF(H224=0, 0, MAX(0, L224-N224-O224-P224)) -> 0 | R224: =IF((COUNTIFS('관리항목계정별잔액조회(전월)'!$C:$C, B224, '관리항목계정별잔액조회(전월)'!$B:$B, "외화외상매출금") + COUNTIFS('관리항목계정별잔액조회(전전월)'!$C:$C, B224, '관리항목계정별잔액조회(전전월)'!$B:$B, "외화외상매출금")) > 0, "외화", "국내") -> 국내
C225: =IFERROR(VLOOKUP(B225,거래처별담당자!C:F,4,0), "#미등록") -> #미등록 | D225: =IF(ISNUMBER(SEARCH("애터미_수출",B225)),"애터미_수출",IF(ISNUMBER(SEARCH("애터미",B225)),"애터미",IF(ISNUMBER(SEARCH("매나테크",B225)),"매나테크",IF(ISNUMBER(SEARCH("Mannatech, Incorporated",B225)),"매나테크",IFERROR(VLOOKUP(B225,거래처별담당자!C:F,3,0),"#미등록"))))) -> #미등록 | E225: =SUMIF('관리항목계정별잔액조회(전월)'!$C:$C,B225,'관리항목계정별잔액조회(전월)'!$D:$D) -> 0 | F225: =SUMIF('관리항목계정별잔액조회(전월)'!$C:$C,B225,'관리항목계정별잔액조회(전월)'!$E:$E) -> 0 | G225: =SUMIF('관리항목계정별잔액조회(전월)'!$C:$C,B225,'관리항목계정별잔액조회(전월)'!$F:$F) -> 0 | H225: =SUMIF('관리항목계정별잔액조회(전월)'!$C:$C,B225,'관리항목계정별잔액조회(전월)'!$G:$G) -> 0 | I225: =SUMIFS(거래명세서품목조회!BK:BK, 거래명세서품목조회!BX:BX, B225, 거래명세서품목조회!G:G, "<"&(EOMONTH($B$3, -1)+1))+SUMIFS(부서별전표작성조회!$I:$I,부서별전표작성조회!$AG:$AG,B225,부서별전표작성조회!$F:$F,"국내외상매출금",부서별전표작성조회!$V:$V,"") -> 0 | J225: =SUMIFS(거래명세서품목조회!AN:AN, 거래명세서품목조회!BX:BX, B225, 거래명세서품목조회!G:G, ">="&(EOMONTH($B$3, -1)+1), 거래명세서품목조회!G:G, "<="&EOMONTH($B$3, 0)) -> 0 | K225: =SUMIFS('입금다중입력(잔액기준)'!$O:$O, '입금다중입력(잔액기준)'!$E:$E, B225, '입금다중입력(잔액기준)'!$M:$M, "국내외상매출금") -> 0 | L225: =IFERROR(H225+I225+J225-K225,0) -> 0 | M225: =SUMIFS(거래명세서품목조회!BK:BK, 거래명세서품목조회!BX:BX, B225, 거래명세서품목조회!G:G, "<="&(INT($B$4)-30)) -> 0 | N225: =MIN(L225, I225+J225) -> 0 | O225: =MIN(MAX(0, L225-N225), F225) -> 0 | P225: =MIN(MAX(0, L225-N225-O225), IFERROR(VLOOKUP(B225, '관리항목계정별잔액조회(전전월)'!$C:$E, 3, FALSE), 0)) -> 0 | Q225: =IF(H225=0, 0, MAX(0, L225-N225-O225-P225)) -> 0 | R225: =IF((COUNTIFS('관리항목계정별잔액조회(전월)'!$C:$C, B225, '관리항목계정별잔액조회(전월)'!$B:$B, "외화외상매출금") + COUNTIFS('관리항목계정별잔액조회(전전월)'!$C:$C, B225, '관리항목계정별잔액조회(전전월)'!$B:$B, "외화외상매출금")) > 0, "외화", "국내") -> 국내
C226: =IFERROR(VLOOKUP(B226,거래처별담당자!C:F,4,0), "#미등록") -> #미등록 | D226: =IF(ISNUMBER(SEARCH("애터미_수출",B226)),"애터미_수출",IF(ISNUMBER(SEARCH("애터미",B226)),"애터미",IF(ISNUMBER(SEARCH("매나테크",B226)),"매나테크",IF(ISNUMBER(SEARCH("Mannatech, Incorporated",B226)),"매나테크",IFERROR(VLOOKUP(B226,거래처별담당자!C:F,3,0),"#미등록"))))) -> #미등록 | E226: =SUMIF('관리항목계정별잔액조회(전월)'!$C:$C,B226,'관리항목계정별잔액조회(전월)'!$D:$D) -> 0 | F226: =SUMIF('관리항목계정별잔액조회(전월)'!$C:$C,B226,'관리항목계정별잔액조회(전월)'!$E:$E) -> 0 | G226: =SUMIF('관리항목계정별잔액조회(전월)'!$C:$C,B226,'관리항목계정별잔액조회(전월)'!$F:$F) -> 0 | H226: =SUMIF('관리항목계정별잔액조회(전월)'!$C:$C,B226,'관리항목계정별잔액조회(전월)'!$G:$G) -> 0 | I226: =SUMIFS(거래명세서품목조회!BK:BK, 거래명세서품목조회!BX:BX, B226, 거래명세서품목조회!G:G, "<"&(EOMONTH($B$3, -1)+1))+SUMIFS(부서별전표작성조회!$I:$I,부서별전표작성조회!$AG:$AG,B226,부서별전표작성조회!$F:$F,"국내외상매출금",부서별전표작성조회!$V:$V,"") -> 0 | J226: =SUMIFS(거래명세서품목조회!AN:AN, 거래명세서품목조회!BX:BX, B226, 거래명세서품목조회!G:G, ">="&(EOMONTH($B$3, -1)+1), 거래명세서품목조회!G:G, "<="&EOMONTH($B$3, 0)) -> 0 | K226: =SUMIFS('입금다중입력(잔액기준)'!$O:$O, '입금다중입력(잔액기준)'!$E:$E, B226, '입금다중입력(잔액기준)'!$M:$M, "국내외상매출금") -> 0 | L226: =IFERROR(H226+I226+J226-K226,0) -> 0 | M226: =SUMIFS(거래명세서품목조회!BK:BK, 거래명세서품목조회!BX:BX, B226, 거래명세서품목조회!G:G, "<="&(INT($B$4)-30)) -> 0 | N226: =MIN(L226, I226+J226) -> 0 | O226: =MIN(MAX(0, L226-N226), F226) -> 0 | P226: =MIN(MAX(0, L226-N226-O226), IFERROR(VLOOKUP(B226, '관리항목계정별잔액조회(전전월)'!$C:$E, 3, FALSE), 0)) -> 0 | Q226: =IF(H226=0, 0, MAX(0, L226-N226-O226-P226)) -> 0 | R226: =IF((COUNTIFS('관리항목계정별잔액조회(전월)'!$C:$C, B226, '관리항목계정별잔액조회(전월)'!$B:$B, "외화외상매출금") + COUNTIFS('관리항목계정별잔액조회(전전월)'!$C:$C, B226, '관리항목계정별잔액조회(전전월)'!$B:$B, "외화외상매출금")) > 0, "외화", "국내") -> 국내
C227: =IFERROR(VLOOKUP(B227,거래처별담당자!C:F,4,0), "#미등록") -> #미등록 | D227: =IF(ISNUMBER(SEARCH("애터미_수출",B227)),"애터미_수출",IF(ISNUMBER(SEARCH("애터미",B227)),"애터미",IF(ISNUMBER(SEARCH("매나테크",B227)),"매나테크",IF(ISNUMBER(SEARCH("Mannatech, Incorporated",B227)),"매나테크",IFERROR(VLOOKUP(B227,거래처별담당자!C:F,3,0),"#미등록"))))) -> #미등록 | E227: =SUMIF('관리항목계정별잔액조회(전월)'!$C:$C,B227,'관리항목계정별잔액조회(전월)'!$D:$D) -> 0 | F227: =SUMIF('관리항목계정별잔액조회(전월)'!$C:$C,B227,'관리항목계정별잔액조회(전월)'!$E:$E) -> 0 | G227: =SUMIF('관리항목계정별잔액조회(전월)'!$C:$C,B227,'관리항목계정별잔액조회(전월)'!$F:$F) -> 0 | H227: =SUMIF('관리항목계정별잔액조회(전월)'!$C:$C,B227,'관리항목계정별잔액조회(전월)'!$G:$G) -> 0 | I227: =SUMIFS(거래명세서품목조회!BK:BK, 거래명세서품목조회!BX:BX, B227, 거래명세서품목조회!G:G, "<"&(EOMONTH($B$3, -1)+1))+SUMIFS(부서별전표작성조회!$I:$I,부서별전표작성조회!$AG:$AG,B227,부서별전표작성조회!$F:$F,"국내외상매출금",부서별전표작성조회!$V:$V,"") -> 0 | J227: =SUMIFS(거래명세서품목조회!AN:AN, 거래명세서품목조회!BX:BX, B227, 거래명세서품목조회!G:G, ">="&(EOMONTH($B$3, -1)+1), 거래명세서품목조회!G:G, "<="&EOMONTH($B$3, 0)) -> 0 | K227: =SUMIFS('입금다중입력(잔액기준)'!$O:$O, '입금다중입력(잔액기준)'!$E:$E, B227, '입금다중입력(잔액기준)'!$M:$M, "국내외상매출금") -> 0 | L227: =IFERROR(H227+I227+J227-K227,0) -> 0 | M227: =SUMIFS(거래명세서품목조회!BK:BK, 거래명세서품목조회!BX:BX, B227, 거래명세서품목조회!G:G, "<="&(INT($B$4)-30)) -> 0 | N227: =MIN(L227, I227+J227) -> 0 | O227: =MIN(MAX(0, L227-N227), F227) -> 0 | P227: =MIN(MAX(0, L227-N227-O227), IFERROR(VLOOKUP(B227, '관리항목계정별잔액조회(전전월)'!$C:$E, 3, FALSE), 0)) -> 0 | Q227: =IF(H227=0, 0, MAX(0, L227-N227-O227-P227)) -> 0 | R227: =IF((COUNTIFS('관리항목계정별잔액조회(전월)'!$C:$C, B227, '관리항목계정별잔액조회(전월)'!$B:$B, "외화외상매출금") + COUNTIFS('관리항목계정별잔액조회(전전월)'!$C:$C, B227, '관리항목계정별잔액조회(전전월)'!$B:$B, "외화외상매출금")) > 0, "외화", "국내") -> 국내
C228: =IFERROR(VLOOKUP(B228,거래처별담당자!C:F,4,0), "#미등록") -> #미등록 | D228: =IF(ISNUMBER(SEARCH("애터미_수출",B228)),"애터미_수출",IF(ISNUMBER(SEARCH("애터미",B228)),"애터미",IF(ISNUMBER(SEARCH("매나테크",B228)),"매나테크",IF(ISNUMBER(SEARCH("Mannatech, Incorporated",B228)),"매나테크",IFERROR(VLOOKUP(B228,거래처별담당자!C:F,3,0),"#미등록"))))) -> #미등록 | E228: =SUMIF('관리항목계정별잔액조회(전월)'!$C:$C,B228,'관리항목계정별잔액조회(전월)'!$D:$D) -> 0 | F228: =SUMIF('관리항목계정별잔액조회(전월)'!$C:$C,B228,'관리항목계정별잔액조회(전월)'!$E:$E) -> 0 | G228: =SUMIF('관리항목계정별잔액조회(전월)'!$C:$C,B228,'관리항목계정별잔액조회(전월)'!$F:$F) -> 0 | H228: =SUMIF('관리항목계정별잔액조회(전월)'!$C:$C,B228,'관리항목계정별잔액조회(전월)'!$G:$G) -> 0 | I228: =SUMIFS(거래명세서품목조회!BK:BK, 거래명세서품목조회!BX:BX, B228, 거래명세서품목조회!G:G, "<"&(EOMONTH($B$3, -1)+1))+SUMIFS(부서별전표작성조회!$I:$I,부서별전표작성조회!$AG:$AG,B228,부서별전표작성조회!$F:$F,"국내외상매출금",부서별전표작성조회!$V:$V,"") -> 0 | J228: =SUMIFS(거래명세서품목조회!AN:AN, 거래명세서품목조회!BX:BX, B228, 거래명세서품목조회!G:G, ">="&(EOMONTH($B$3, -1)+1), 거래명세서품목조회!G:G, "<="&EOMONTH($B$3, 0)) -> 0 | K228: =SUMIFS('입금다중입력(잔액기준)'!$O:$O, '입금다중입력(잔액기준)'!$E:$E, B228, '입금다중입력(잔액기준)'!$M:$M, "국내외상매출금") -> 0 | L228: =IFERROR(H228+I228+J228-K228,0) -> 0 | M228: =SUMIFS(거래명세서품목조회!BK:BK, 거래명세서품목조회!BX:BX, B228, 거래명세서품목조회!G:G, "<="&(INT($B$4)-30)) -> 0 | N228: =MIN(L228, I228+J228) -> 0 | O228: =MIN(MAX(0, L228-N228), F228) -> 0 | P228: =MIN(MAX(0, L228-N228-O228), IFERROR(VLOOKUP(B228, '관리항목계정별잔액조회(전전월)'!$C:$E, 3, FALSE), 0)) -> 0 | Q228: =IF(H228=0, 0, MAX(0, L228-N228-O228-P228)) -> 0 | R228: =IF((COUNTIFS('관리항목계정별잔액조회(전월)'!$C:$C, B228, '관리항목계정별잔액조회(전월)'!$B:$B, "외화외상매출금") + COUNTIFS('관리항목계정별잔액조회(전전월)'!$C:$C, B228, '관리항목계정별잔액조회(전전월)'!$B:$B, "외화외상매출금")) > 0, "외화", "국내") -> 국내
C229: =IFERROR(VLOOKUP(B229,거래처별담당자!C:F,4,0), "#미등록") -> #미등록 | D229: =IF(ISNUMBER(SEARCH("애터미_수출",B229)),"애터미_수출",IF(ISNUMBER(SEARCH("애터미",B229)),"애터미",IF(ISNUMBER(SEARCH("매나테크",B229)),"매나테크",IF(ISNUMBER(SEARCH("Mannatech, Incorporated",B229)),"매나테크",IFERROR(VLOOKUP(B229,거래처별담당자!C:F,3,0),"#미등록"))))) -> #미등록 | E229: =SUMIF('관리항목계정별잔액조회(전월)'!$C:$C,B229,'관리항목계정별잔액조회(전월)'!$D:$D) -> 0 | F229: =SUMIF('관리항목계정별잔액조회(전월)'!$C:$C,B229,'관리항목계정별잔액조회(전월)'!$E:$E) -> 0 | G229: =SUMIF('관리항목계정별잔액조회(전월)'!$C:$C,B229,'관리항목계정별잔액조회(전월)'!$F:$F) -> 0 | H229: =SUMIF('관리항목계정별잔액조회(전월)'!$C:$C,B229,'관리항목계정별잔액조회(전월)'!$G:$G) -> 0 | I229: =SUMIFS(거래명세서품목조회!BK:BK, 거래명세서품목조회!BX:BX, B229, 거래명세서품목조회!G:G, "<"&(EOMONTH($B$3, -1)+1))+SUMIFS(부서별전표작성조회!$I:$I,부서별전표작성조회!$AG:$AG,B229,부서별전표작성조회!$F:$F,"국내외상매출금",부서별전표작성조회!$V:$V,"") -> 0 | J229: =SUMIFS(거래명세서품목조회!AN:AN, 거래명세서품목조회!BX:BX, B229, 거래명세서품목조회!G:G, ">="&(EOMONTH($B$3, -1)+1), 거래명세서품목조회!G:G, "<="&EOMONTH($B$3, 0)) -> 0 | K229: =SUMIFS('입금다중입력(잔액기준)'!$O:$O, '입금다중입력(잔액기준)'!$E:$E, B229, '입금다중입력(잔액기준)'!$M:$M, "국내외상매출금") -> 0 | L229: =IFERROR(H229+I229+J229-K229,0) -> 0 | M229: =SUMIFS(거래명세서품목조회!BK:BK, 거래명세서품목조회!BX:BX, B229, 거래명세서품목조회!G:G, "<="&(INT($B$4)-30)) -> 0 | N229: =MIN(L229, I229+J229) -> 0 | O229: =MIN(MAX(0, L229-N229), F229) -> 0 | P229: =MIN(MAX(0, L229-N229-O229), IFERROR(VLOOKUP(B229, '관리항목계정별잔액조회(전전월)'!$C:$E, 3, FALSE), 0)) -> 0 | Q229: =IF(H229=0, 0, MAX(0, L229-N229-O229-P229)) -> 0 | R229: =IF((COUNTIFS('관리항목계정별잔액조회(전월)'!$C:$C, B229, '관리항목계정별잔액조회(전월)'!$B:$B, "외화외상매출금") + COUNTIFS('관리항목계정별잔액조회(전전월)'!$C:$C, B229, '관리항목계정별잔액조회(전전월)'!$B:$B, "외화외상매출금")) > 0, "외화", "국내") -> 국내
...

Sheet 거래명세서품목조회
